[32mINFO    [0m juju.model:__init__.py:3254 Waiting for model:
  vault-b/0 [idle] active: 
  vault-b/1 [idle] active: 
  vault-b/2 [idle] active: 
[32mINFO    [0m juju.model:__init__.py:3254 Waiting for model:
  vault-b/0 [idle] active: 
  vault-b/1 [idle] active: 
  vault-b/2 [idle] active:
[32mINFO    [0m pytest_operator.plugin:plugin.py:936 Model status:

Model                  Controller                Cloud/Region        Version  SLA          Timestamp
test-integration-idmz  github-pr-535ee-microk8s  microk8s/localhost  3.6.2    unsupported  02:13:06Z

App        Version  Status  Scale  Charm      Channel  Rev  Address         Exposed  Message
vault-b             active      3  vault-k8s             1  10.152.183.193  no       
vault-k8s           active      3  vault-k8s             0  10.152.183.120  no       

Unit          Workload  Agent      Address     Ports  Message
vault-b/0*    active    executing  10.1.53.12         
vault-b/1     active    executing  10.1.53.4          
vault-b/2     active    executing  10.1.53.13         
vault-k8s/0*  active    executing  10.1.53.16         
vault-k8s/1   active    executing  10.1.53.25         
vault-k8s/2   active    executing  10.1.53.23         

[32mINFO    [0m pytest_operator.plugin:plugin.py:942 Juju error logs:

unit-vault-k8s-1: 01:51:35 ERROR unit.vault-k8s/1.juju-log [vault_client] Error while checking Vault health status: HTTPSConnectionPool(host='vault-k8s-1.vault-k8s-endpoints.test-integration-idmz.svc.cluster.local', port=8200): Max retries exceeded with url: /v1/sys/health (Caused by NewConnectionError('<urllib3.connection.HTTPSConnection object at 0x7c3591b3c250>: Failed to establish a new connection: [Errno 111] Connection refused'))
controller-0: 02:08:26 ERROR juju.worker.caasunitprovisioner stopping application worker for minio: Operation cannot be fulfilled on statefulsets.apps "minio": StorageError: invalid object, Code: 4, Key: /registry/statefulsets/test-integration-idmz/minio, ResourceVersion: 0, AdditionalErrorMsg: Precondition failed: UID in precondition: 4731371e-15f4-424e-8f90-9d8eb976babb, UID in object meta: 
unit-vault-b-0: 02:12:03 ERROR unit.vault-b/0.juju-log [vault_client] Error while checking Vault health status: HTTPSConnectionPool(host='vault-b-0.vault-b-endpoints.test-integration-idmz.svc.cluster.local', port=8200): Max retries exceeded with url: /v1/sys/health (Caused by NewConnectionError('<urllib3.connection.HTTPSConnection object at 0x7aea7a713790>: Failed to establish a new connection: [Errno 111] Connection refused'))
unit-vault-b-1: 02:12:37 ERROR unit.vault-b/1.juju-log [vault_client] Error while checking Vault health status: HTTPSConnectionPool(host='vault-b-1.vault-b-endpoints.test-integration-idmz.svc.cluster.local', port=8200): Max retries exceeded with url: /v1/sys/health (Caused by NewConnectionError('<urllib3.connection.HTTPSConnection object at 0x72c59cd00310>: Failed to establish a new connection: [Errno 111] Connection refused'))
unit-vault-b-2: 02:12:37 ERROR unit.vault-b/2.juju-log [vault_client] Error while checking Vault health status: HTTPSConnectionPool(host='vault-b-2.vault-b-endpoints.test-integration-idmz.svc.cluster.local', port=8200): Max retries exceeded with url: /v1/sys/health (Caused by NewConnectionError('<urllib3.connection.HTTPSConnection object at 0x79d4733282e0>: Failed to establish a new connection: [Errno 111] Connection refused'))
unit-vault-b-0: 02:12:38 ERROR unit.vault-b/0.juju-log [vault_client] Error while checking Vault health status: HTTPSConnectionPool(host='vault-b-0.vault-b-endpoints.test-integration-idmz.svc.cluster.local', port=8200): Max retries exceeded with url: /v1/sys/health (Caused by NewConnectionError('<urllib3.connection.HTTPSConnection object at 0x7cc5d8930250>: Failed to establish a new connection: [Errno 111] Connection refused'))

[32mINFO    [0m pytest_operator.plugin:plugin.py:1048 Resetting model test-integration-idmz...
[32mINFO    [0m pytest_operator.plugin:plugin.py:1037    Destroying applications vault-k8s
[32mINFO    [0m pytest_operator.plugin:plugin.py:1037    Destroying applications vault-b
[32mINFO    [0m pytest_operator.plugin:plugin.py:1053 Not waiting on reset to complete.
[32mINFO    [0m pytest_operator.plugin:plugin.py:1024 Forgetting model main...