[32mINFO    [0m juju.model:__init__.py:3254 Waiting for model:
  vault-b/0 [idle] active: 
  vault-b/1 [idle] active: 
  vault-b/2 [idle] active: 
[32mINFO    [0m juju.model:__init__.py:3254 Waiting for model:
  vault-b/0 [idle] active: 
  vault-b/1 [idle] active: 
  vault-b/2 [idle] active:
[32mINFO    [0m pytest_operator.plugin:plugin.py:951 Model status:

Model                 Controller                Cloud/Region        Version  SLA          Timestamp
test-autounseal-knty  github-pr-4987b-microk8s  microk8s/localhost  3.6.9    unsupported  14:31:19Z

App        Version  Status  Scale  Charm      Channel  Rev  Address         Exposed  Message
vault-b             active      3  vault-k8s             0  10.152.183.253  no       
vault-k8s           active      3  vault-k8s             1  10.152.183.182  no       

Unit          Workload  Agent  Address       Ports  Message
vault-b/0*    active    idle   10.1.113.168         
vault-b/1     active    idle   10.1.113.170         
vault-b/2     active    idle   10.1.113.169         
vault-k8s/0*  active    idle   10.1.113.150         
vault-k8s/1   active    idle   10.1.113.156         
vault-k8s/2   active    idle   10.1.113.157         

[32mINFO    [0m pytest_operator.plugin:plugin.py:957 Juju error logs:

unit-vault-k8s-1: 14:25:24 ERROR unit.vault-k8s/1.juju-log [vault_client] Error while checking Vault health status: HTTPSConnectionPool(host='vault-k8s-1.vault-k8s-endpoints.test-autounseal-knty.svc.cluster.local', port=8200): Max retries exceeded with url: /v1/sys/health (Caused by NewConnectionError('<urllib3.connection.HTTPSConnection object at 0x7fa1be78ae70>: Failed to establish a new connection: [Errno 111] Connection refused'))
unit-vault-k8s-1: 14:25:26 ERROR unit.vault-k8s/1.juju-log [vault_client] Error while checking Vault health status: HTTPSConnectionPool(host='vault-k8s-1.vault-k8s-endpoints.test-autounseal-knty.svc.cluster.local', port=8200): Max retries exceeded with url: /v1/sys/health (Caused by NewConnectionError('<urllib3.connection.HTTPSConnection object at 0x7f4e76e1f650>: Failed to establish a new connection: [Errno 111] Connection refused'))
unit-vault-k8s-2: 14:25:27 ERROR unit.vault-k8s/2.juju-log [vault_client] Error while checking Vault health status: HTTPSConnectionPool(host='vault-k8s-2.vault-k8s-endpoints.test-autounseal-knty.svc.cluster.local', port=8200): Max retries exceeded with url: /v1/sys/health (Caused by NewConnectionError('<urllib3.connection.HTTPSConnection object at 0x7fb6985a51c0>: Failed to establish a new connection: [Errno 111] Connection refused'))
unit-vault-k8s-1: 14:25:28 ERROR unit.vault-k8s/1.juju-log vault-peers:1: [vault_client] Error while checking Vault health status: HTTPSConnectionPool(host='vault-k8s-1.vault-k8s-endpoints.test-autounseal-knty.svc.cluster.local', port=8200): Max retries exceeded with url: /v1/sys/health (Caused by NewConnectionError('<urllib3.connection.HTTPSConnection object at 0x7fe57873f1d0>: Failed to establish a new connection: [Errno 111] Connection refused'))
unit-vault-k8s-2: 14:25:29 ERROR unit.vault-k8s/2.juju-log [vault_client] Error while checking Vault health status: HTTPSConnectionPool(host='vault-k8s-2.vault-k8s-endpoints.test-autounseal-knty.svc.cluster.local', port=8200): Max retries exceeded with url: /v1/sys/health (Caused by NewConnectionError('<urllib3.connection.HTTPSConnection object at 0x7fd532e37a10>: Failed to establish a new connection: [Errno 111] Connection refused'))
unit-vault-k8s-2: 14:25:30 ERROR unit.vault-k8s/2.juju-log vault-peers:1: [vault_client] Error while checking Vault health status: HTTPSConnectionPool(host='vault-k8s-2.vault-k8s-endpoints.test-autounseal-knty.svc.cluster.local', port=8200): Max retries exceeded with url: /v1/sys/health (Caused by NewConnectionError('<urllib3.connection.HTTPSConnection object at 0x7fc0e4e23590>: Failed to establish a new connection: [Errno 111] Connection refused'))
unit-vault-b-1: 14:28:30 ERROR unit.vault-b/1.juju-log [vault_client] Error while checking Vault health status: HTTPSConnectionPool(host='vault-b-1.vault-b-endpoints.test-autounseal-knty.svc.cluster.local', port=8200): Max retries exceeded with url: /v1/sys/health (Caused by NewConnectionError('<urllib3.connection.HTTPSConnection object at 0x7f69674c5070>: Failed to establish a new connection: [Errno 111] Connection refused'))
unit-vault-b-1: 14:28:32 ERROR unit.vault-b/1.juju-log [vault_client] Error while checking Vault health status: HTTPSConnectionPool(host='vault-b-1.vault-b-endpoints.test-autounseal-knty.svc.cluster.local', port=8200): Max retries exceeded with url: /v1/sys/health (Caused by NewConnectionError('<urllib3.connection.HTTPSConnection object at 0x7fa811e6de80>: Failed to establish a new connection: [Errno 111] Connection refused'))
unit-vault-b-1: 14:28:34 ERROR unit.vault-b/1.juju-log vault-autounseal-requires:2: [vault_client] Error while checking Vault health status: HTTPSConnectionPool(host='vault-b-1.vault-b-endpoints.test-autounseal-knty.svc.cluster.local', port=8200): Max retries exceeded with url: /v1/sys/health (Caused by NewConnectionError('<urllib3.connection.HTTPSConnection object at 0x7fbcb1e39850>: Failed to establish a new connection: [Errno 111] Connection refused'))
unit-vault-b-1: 14:28:36 ERROR unit.vault-b/1.juju-log vault-autounseal-requires:2: [vault_client] Error while checking Vault health status: HTTPSConnectionPool(host='vault-b-1.vault-b-endpoints.test-autounseal-knty.svc.cluster.local', port=8200): Max retries exceeded with url: /v1/sys/health (Caused by NewConnectionError('<urllib3.connection.HTTPSConnection object at 0x7fa9bb4e97f0>: Failed to establish a new connection: [Errno 111] Connection refused'))
unit-vault-b-1: 14:28:38 ERROR unit.vault-b/1.juju-log vault-autounseal-requires:2: [vault_client] Error while checking Vault health status: HTTPSConnectionPool(host='vault-b-1.vault-b-endpoints.test-autounseal-knty.svc.cluster.local', port=8200): Max retries exceeded with url: /v1/sys/health (Caused by NewConnectionError('<urllib3.connection.HTTPSConnection object at 0x7f59eed598e0>: Failed to establish a new connection: [Errno 111] Connection refused'))
unit-vault-b-1: 14:28:40 ERROR unit.vault-b/1.juju-log vault-autounseal-requires:2: [vault_client] Error while checking Vault health status: HTTPSConnectionPool(host='vault-b-1.vault-b-endpoints.test-autounseal-knty.svc.cluster.local', port=8200): Max retries exceeded with url: /v1/sys/health (Caused by NewConnectionError('<urllib3.connection.HTTPSConnection object at 0x7f53a1f23b00>: Failed to establish a new connection: [Errno 111] Connection refused'))
unit-vault-b-2: 14:28:41 ERROR unit.vault-b/2.juju-log [vault_client] Error while checking Vault health status: HTTPSConnectionPool(host='vault-b-2.vault-b-endpoints.test-autounseal-knty.svc.cluster.local', port=8200): Max retries exceeded with url: /v1/sys/health (Caused by NewConnectionError('<urllib3.connection.HTTPSConnection object at 0x7fafb3fb0e30>: Failed to establish a new connection: [Errno 111] Connection refused'))
unit-vault-b-1: 14:28:42 ERROR unit.vault-b/1.juju-log vault-autounseal-requires:2: [vault_client] Error while checking Vault health status: HTTPSConnectionPool(host='vault-b-1.vault-b-endpoints.test-autounseal-knty.svc.cluster.local', port=8200): Max retries exceeded with url: /v1/sys/health (Caused by NewConnectionError('<urllib3.connection.HTTPSConnection object at 0x7f193fb55b20>: Failed to establish a new connection: [Errno 111] Connection refused'))
unit-vault-b-2: 14:28:42 ERROR unit.vault-b/2.juju-log [vault_client] Error while checking Vault health status: HTTPSConnectionPool(host='vault-b-2.vault-b-endpoints.test-autounseal-knty.svc.cluster.local', port=8200): Max retries exceeded with url: /v1/sys/health (Caused by NewConnectionError('<urllib3.connection.HTTPSConnection object at 0x7fc128f33650>: Failed to establish a new connection: [Errno 111] Connection refused'))
unit-vault-b-1: 14:28:44 ERROR unit.vault-b/1.juju-log vault-autounseal-requires:2: [vault_client] Error while checking Vault health status: HTTPSConnectionPool(host='vault-b-1.vault-b-endpoints.test-autounseal-knty.svc.cluster.local', port=8200): Max retries exceeded with url: /v1/sys/health (Caused by NewConnectionError('<urllib3.connection.HTTPSConnection object at 0x7f7f38ef4cb0>: Failed to establish a new connection: [Errno 111] Connection refused'))
unit-vault-b-2: 14:28:45 ERROR unit.vault-b/2.juju-log vault-autounseal-requires:2: [vault_client] Error while checking Vault health status: HTTPSConnectionPool(host='vault-b-2.vault-b-endpoints.test-autounseal-knty.svc.cluster.local', port=8200): Max retries exceeded with url: /v1/sys/health (Caused by NewConnectionError('<urllib3.connection.HTTPSConnection object at 0x7f8d47d35c40>: Failed to establish a new connection: [Errno 111] Connection refused'))
unit-vault-b-1: 14:28:46 ERROR unit.vault-b/1.juju-log vault-autounseal-requires:2: [vault_client] Error while checking Vault health status: HTTPSConnectionPool(host='vault-b-1.vault-b-endpoints.test-autounseal-knty.svc.cluster.local', port=8200): Max retries exceeded with url: /v1/sys/health (Caused by NewConnectionError('<urllib3.connection.HTTPSConnection object at 0x7f45cab35970>: Failed to establish a new connection: [Errno 111] Connection refused'))
unit-vault-b-2: 14:28:47 ERROR unit.vault-b/2.juju-log vault-autounseal-requires:2: [vault_client] Error while checking Vault health status: HTTPSConnectionPool(host='vault-b-2.vault-b-endpoints.test-autounseal-knty.svc.cluster.local', port=8200): Max retries exceeded with url: /v1/sys/health (Caused by NewConnectionError('<urllib3.connection.HTTPSConnection object at 0x7f4e650ad460>: Failed to establish a new connection: [Errno 111] Connection refused'))
unit-vault-b-1: 14:28:48 ERROR unit.vault-b/1.juju-log vault-peers:0: [vault_client] Error while checking Vault health status: HTTPSConnectionPool(host='vault-b-1.vault-b-endpoints.test-autounseal-knty.svc.cluster.local', port=8200): Max retries exceeded with url: /v1/sys/health (Caused by NewConnectionError('<urllib3.connection.HTTPSConnection object at 0x7fbb97f0e6c0>: Failed to establish a new connection: [Errno 111] Connection refused'))
unit-vault-b-2: 14:28:49 ERROR unit.vault-b/2.juju-log vault-autounseal-requires:2: [vault_client] Error while checking Vault health status: HTTPSConnectionPool(host='vault-b-2.vault-b-endpoints.test-autounseal-knty.svc.cluster.local', port=8200): Max retries exceeded with url: /v1/sys/health (Caused by NewConnectionError('<urllib3.connection.HTTPSConnection object at 0x7f37e9759cd0>: Failed to establish a new connection: [Errno 111] Connection refused'))
unit-vault-b-2: 14:28:50 ERROR unit.vault-b/2.juju-log vault-autounseal-requires:2: [vault_client] Error while checking Vault health status: HTTPSConnectionPool(host='vault-b-2.vault-b-endpoints.test-autounseal-knty.svc.cluster.local', port=8200): Max retries exceeded with url: /v1/sys/health (Caused by NewConnectionError('<urllib3.connection.HTTPSConnection object at 0x7f0392eca030>: Failed to establish a new connection: [Errno 111] Connection refused'))
unit-vault-b-2: 14:28:53 ERROR unit.vault-b/2.juju-log vault-autounseal-requires:2: [vault_client] Error while checking Vault health status: HTTPSConnectionPool(host='vault-b-2.vault-b-endpoints.test-autounseal-knty.svc.cluster.local', port=8200): Max retries exceeded with url: /v1/sys/health (Caused by NewConnectionError('<urllib3.connection.HTTPSConnection object at 0x7f1070335d00>: Failed to establish a new connection: [Errno 111] Connection refused'))
unit-vault-b-2: 14:28:55 ERROR unit.vault-b/2.juju-log vault-autounseal-requires:2: [vault_client] Error while checking Vault health status: HTTPSConnectionPool(host='vault-b-2.vault-b-endpoints.test-autounseal-knty.svc.cluster.local', port=8200): Max retries exceeded with url: /v1/sys/health (Caused by NewConnectionError('<urllib3.connection.HTTPSConnection object at 0x7f27d09620c0>: Failed to establish a new connection: [Errno 111] Connection refused'))
unit-vault-b-2: 14:28:57 ERROR unit.vault-b/2.juju-log vault-autounseal-requires:2: [vault_client] Error while checking Vault health status: HTTPSConnectionPool(host='vault-b-2.vault-b-endpoints.test-autounseal-knty.svc.cluster.local', port=8200): Max retries exceeded with url: /v1/sys/health (Caused by NewConnectionError('<urllib3.connection.HTTPSConnection object at 0x7f47d7439c10>: Failed to establish a new connection: [Errno 111] Connection refused'))
unit-vault-b-2: 14:28:59 ERROR unit.vault-b/2.juju-log vault-peers:0: [vault_client] Error while checking Vault health status: HTTPSConnectionPool(host='vault-b-2.vault-b-endpoints.test-autounseal-knty.svc.cluster.local', port=8200): Max retries exceeded with url: /v1/sys/health (Caused by NewConnectionError('<urllib3.connection.HTTPSConnection object at 0x7f43fff0e5d0>: Failed to establish a new connection: [Errno 111] Connection refused'))
unit-vault-b-0: 14:29:47 ERROR unit.vault-b/0.juju-log [vault_client] Error while checking Vault health status: HTTPSConnectionPool(host='vault-b-0.vault-b-endpoints.test-autounseal-knty.svc.cluster.local', port=8200): Max retries exceeded with url: /v1/sys/health (Caused by NewConnectionError('<urllib3.connection.HTTPSConnection object at 0x7f54b5e3f440>: Failed to establish a new connection: [Errno 111] Connection refused'))
unit-vault-b-0: 14:30:12 ERROR unit.vault-b/0.juju-log [vault_client] Error while checking Vault health status: HTTPSConnectionPool(host='vault-b-0.vault-b-endpoints.test-autounseal-knty.svc.cluster.local', port=8200): Max retries exceeded with url: /v1/sys/health (Caused by NewConnectionError('<urllib3.connection.HTTPSConnection object at 0x7f3c1c8a2000>: Failed to establish a new connection: [Errno 111] Connection refused'))
unit-vault-b-2: 14:30:16 ERROR unit.vault-b/2.juju-log [vault_client] Error while checking Vault health status: HTTPSConnectionPool(host='vault-b-2.vault-b-endpoints.test-autounseal-knty.svc.cluster.local', port=8200): Max retries exceeded with url: /v1/sys/health (Caused by NewConnectionError('<urllib3.connection.HTTPSConnection object at 0x7f73a88a22d0>: Failed to establish a new connection: [Errno 111] Connection refused'))
unit-vault-b-1: 14:30:17 ERROR unit.vault-b/1.juju-log [vault_client] Error while checking Vault health status: HTTPSConnectionPool(host='vault-b-1.vault-b-endpoints.test-autounseal-knty.svc.cluster.local', port=8200): Max retries exceeded with url: /v1/sys/health (Caused by NewConnectionError('<urllib3.connection.HTTPSConnection object at 0x7ff5f5b982c0>: Failed to establish a new connection: [Errno 111] Connection refused'))
model-4360a370-90e4-4134-843e-61da280aa602: 14:30:20 ERROR juju.worker.dependency "log-sender" manifold worker returned unexpected error: sending log message: websocket: close 1005 (no status): websocket: close sent
unit-vault-k8s-2: 14:30:26 ERROR juju.worker.dependency "log-sender" manifold worker returned unexpected error: sending log message: websocket: close 1005 (no status): websocket: close sent
unit-vault-b-2: 14:30:26 ERROR juju.worker.dependency "log-sender" manifold worker returned unexpected error: sending log message: websocket: close 1005 (no status): websocket: close sent
unit-vault-b-1: 14:30:26 ERROR juju.worker.dependency "log-sender" manifold worker returned unexpected error: sending log message: websocket: close 1005 (no status): websocket: close sent
unit-vault-k8s-0: 14:30:29 ERROR juju.worker.dependency "log-sender" manifold worker returned unexpected error: sending log message: websocket: close 1005 (no status): websocket: close sent
unit-vault-k8s-1: 14:30:30 ERROR juju.worker.dependency "log-sender" manifold worker returned unexpected error: sending log message: websocket: close 1005 (no status): websocket: close sent
unit-vault-b-0: 14:30:32 ERROR juju.worker.dependency "log-sender" manifold worker returned unexpected error: sending log message: websocket: close 1005 (no status): websocket: close sent

[32mINFO    [0m pytest_operator.plugin:plugin.py:1063 Resetting model test-autounseal-knty...
[32mINFO    [0m pytest_operator.plugin:plugin.py:1052    Destroying applications vault-b
[32mINFO    [0m pytest_operator.plugin:plugin.py:1052    Destroying applications vault-k8s
[32mINFO    [0m pytest_operator.plugin:plugin.py:1068 Not waiting on reset to complete.
[32mINFO    [0m pytest_operator.plugin:plugin.py:1039 Forgetting model main...