[32mINFO    [0m juju.model:__init__.py:3254 Waiting for model:
  vault-b/0 [idle] active: 
  vault-b/2 [idle] active: 
  vault-b/1 [idle] active: 
[32mINFO    [0m juju.model:__init__.py:3254 Waiting for model:
  vault-b/0 [idle] active: 
  vault-b/2 [idle] active: 
  vault-b/1 [idle] active:
[32mINFO    [0m pytest_operator.plugin:plugin.py:951 Model status:

Model                 Controller                Cloud/Region        Version  SLA          Timestamp
test-autounseal-r8x0  github-pr-2104c-microk8s  microk8s/localhost  3.6.9    unsupported  16:39:19Z

App        Version  Status  Scale  Charm      Channel  Rev  Address         Exposed  Message
vault-b             active      3  vault-k8s             0  10.152.183.110  no       
vault-k8s           active      3  vault-k8s             1  10.152.183.152  no       

Unit          Workload  Agent  Address    Ports  Message
vault-b/0*    active    idle   10.1.7.42         
vault-b/1     active    idle   10.1.7.41         
vault-b/2     active    idle   10.1.7.40         
vault-k8s/0*  active    idle   10.1.7.26         
vault-k8s/1   active    idle   10.1.7.29         
vault-k8s/2   active    idle   10.1.7.28         

[32mINFO    [0m pytest_operator.plugin:plugin.py:957 Juju error logs:

unit-vault-k8s-2: 16:33:35 ERROR unit.vault-k8s/2.juju-log [vault_client] Error while checking Vault health status: HTTPSConnectionPool(host='vault-k8s-2.vault-k8s-endpoints.test-autounseal-r8x0.svc.cluster.local', port=8200): Max retries exceeded with url: /v1/sys/health (Caused by NewConnectionError('<urllib3.connection.HTTPSConnection object at 0x7f387568c5c0>: Failed to establish a new connection: [Errno 111] Connection refused'))
unit-vault-k8s-2: 16:33:37 ERROR unit.vault-k8s/2.juju-log [vault_client] Error while checking Vault health status: HTTPSConnectionPool(host='vault-k8s-2.vault-k8s-endpoints.test-autounseal-r8x0.svc.cluster.local', port=8200): Max retries exceeded with url: /v1/sys/health (Caused by NewConnectionError('<urllib3.connection.HTTPSConnection object at 0x7fa2aa9a7e60>: Failed to establish a new connection: [Errno 111] Connection refused'))
unit-vault-k8s-1: 16:33:37 ERROR unit.vault-k8s/1.juju-log [vault_client] Error while checking Vault health status: HTTPSConnectionPool(host='vault-k8s-1.vault-k8s-endpoints.test-autounseal-r8x0.svc.cluster.local', port=8200): Max retries exceeded with url: /v1/sys/health (Caused by NewConnectionError('<urllib3.connection.HTTPSConnection object at 0x7f6890ed7dd0>: Failed to establish a new connection: [Errno 111] Connection refused'))
unit-vault-k8s-2: 16:33:39 ERROR unit.vault-k8s/2.juju-log vault-peers:1: [vault_client] Error while checking Vault health status: HTTPSConnectionPool(host='vault-k8s-2.vault-k8s-endpoints.test-autounseal-r8x0.svc.cluster.local', port=8200): Max retries exceeded with url: /v1/sys/health (Caused by NewConnectionError('<urllib3.connection.HTTPSConnection object at 0x7f4aadeb78f0>: Failed to establish a new connection: [Errno 111] Connection refused'))
unit-vault-k8s-1: 16:33:39 ERROR unit.vault-k8s/1.juju-log [vault_client] Error while checking Vault health status: HTTPSConnectionPool(host='vault-k8s-1.vault-k8s-endpoints.test-autounseal-r8x0.svc.cluster.local', port=8200): Max retries exceeded with url: /v1/sys/health (Caused by NewConnectionError('<urllib3.connection.HTTPSConnection object at 0x7f93687b4080>: Failed to establish a new connection: [Errno 111] Connection refused'))
unit-vault-k8s-1: 16:33:41 ERROR unit.vault-k8s/1.juju-log vault-peers:1: [vault_client] Error while checking Vault health status: HTTPSConnectionPool(host='vault-k8s-1.vault-k8s-endpoints.test-autounseal-r8x0.svc.cluster.local', port=8200): Max retries exceeded with url: /v1/sys/health (Caused by NewConnectionError('<urllib3.connection.HTTPSConnection object at 0x7f7003e88140>: Failed to establish a new connection: [Errno 111] Connection refused'))
unit-vault-b-2: 16:36:45 ERROR unit.vault-b/2.juju-log [vault_client] Error while checking Vault health status: HTTPSConnectionPool(host='vault-b-2.vault-b-endpoints.test-autounseal-r8x0.svc.cluster.local', port=8200): Max retries exceeded with url: /v1/sys/health (Caused by NewConnectionError('<urllib3.connection.HTTPSConnection object at 0x7f1d688fe420>: Failed to establish a new connection: [Errno 111] Connection refused'))
unit-vault-b-1: 16:36:45 ERROR unit.vault-b/1.juju-log [vault_client] Error while checking Vault health status: HTTPSConnectionPool(host='vault-b-1.vault-b-endpoints.test-autounseal-r8x0.svc.cluster.local', port=8200): Max retries exceeded with url: /v1/sys/health (Caused by NewConnectionError('<urllib3.connection.HTTPSConnection object at 0x7f8cd3d795e0>: Failed to establish a new connection: [Errno 111] Connection refused'))
unit-vault-b-2: 16:36:47 ERROR unit.vault-b/2.juju-log [vault_client] Error while checking Vault health status: HTTPSConnectionPool(host='vault-b-2.vault-b-endpoints.test-autounseal-r8x0.svc.cluster.local', port=8200): Max retries exceeded with url: /v1/sys/health (Caused by NewConnectionError('<urllib3.connection.HTTPSConnection object at 0x7ffab08378f0>: Failed to establish a new connection: [Errno 111] Connection refused'))
unit-vault-b-1: 16:36:47 ERROR unit.vault-b/1.juju-log [vault_client] Error while checking Vault health status: HTTPSConnectionPool(host='vault-b-1.vault-b-endpoints.test-autounseal-r8x0.svc.cluster.local', port=8200): Max retries exceeded with url: /v1/sys/health (Caused by NewConnectionError('<urllib3.connection.HTTPSConnection object at 0x7fdd8ad041a0>: Failed to establish a new connection: [Errno 111] Connection refused'))
unit-vault-b-2: 16:36:49 ERROR unit.vault-b/2.juju-log vault-autounseal-requires:2: [vault_client] Error while checking Vault health status: HTTPSConnectionPool(host='vault-b-2.vault-b-endpoints.test-autounseal-r8x0.svc.cluster.local', port=8200): Max retries exceeded with url: /v1/sys/health (Caused by NewConnectionError('<urllib3.connection.HTTPSConnection object at 0x7fde30a12b40>: Failed to establish a new connection: [Errno 111] Connection refused'))
unit-vault-b-1: 16:36:49 ERROR unit.vault-b/1.juju-log vault-autounseal-requires:2: [vault_client] Error while checking Vault health status: HTTPSConnectionPool(host='vault-b-1.vault-b-endpoints.test-autounseal-r8x0.svc.cluster.local', port=8200): Max retries exceeded with url: /v1/sys/health (Caused by NewConnectionError('<urllib3.connection.HTTPSConnection object at 0x7f8b221974d0>: Failed to establish a new connection: [Errno 111] Connection refused'))
unit-vault-b-1: 16:36:51 ERROR unit.vault-b/1.juju-log vault-autounseal-requires:2: [vault_client] Error while checking Vault health status: HTTPSConnectionPool(host='vault-b-1.vault-b-endpoints.test-autounseal-r8x0.svc.cluster.local', port=8200): Max retries exceeded with url: /v1/sys/health (Caused by NewConnectionError('<urllib3.connection.HTTPSConnection object at 0x7f9db773a600>: Failed to establish a new connection: [Errno 111] Connection refused'))
unit-vault-b-2: 16:36:51 ERROR unit.vault-b/2.juju-log vault-autounseal-requires:2: [vault_client] Error while checking Vault health status: HTTPSConnectionPool(host='vault-b-2.vault-b-endpoints.test-autounseal-r8x0.svc.cluster.local', port=8200): Max retries exceeded with url: /v1/sys/health (Caused by NewConnectionError('<urllib3.connection.HTTPSConnection object at 0x7f0a4fba3ef0>: Failed to establish a new connection: [Errno 111] Connection refused'))
unit-vault-b-1: 16:36:53 ERROR unit.vault-b/1.juju-log vault-autounseal-requires:2: [vault_client] Error while checking Vault health status: HTTPSConnectionPool(host='vault-b-1.vault-b-endpoints.test-autounseal-r8x0.svc.cluster.local', port=8200): Max retries exceeded with url: /v1/sys/health (Caused by NewConnectionError('<urllib3.connection.HTTPSConnection object at 0x7f02faec5040>: Failed to establish a new connection: [Errno 111] Connection refused'))
unit-vault-b-2: 16:36:53 ERROR unit.vault-b/2.juju-log vault-autounseal-requires:2: [vault_client] Error while checking Vault health status: HTTPSConnectionPool(host='vault-b-2.vault-b-endpoints.test-autounseal-r8x0.svc.cluster.local', port=8200): Max retries exceeded with url: /v1/sys/health (Caused by NewConnectionError('<urllib3.connection.HTTPSConnection object at 0x7f9d97d66810>: Failed to establish a new connection: [Errno 111] Connection refused'))
unit-vault-b-1: 16:36:55 ERROR unit.vault-b/1.juju-log vault-autounseal-requires:2: [vault_client] Error while checking Vault health status: HTTPSConnectionPool(host='vault-b-1.vault-b-endpoints.test-autounseal-r8x0.svc.cluster.local', port=8200): Max retries exceeded with url: /v1/sys/health (Caused by NewConnectionError('<urllib3.connection.HTTPSConnection object at 0x7fb3d39b8590>: Failed to establish a new connection: [Errno 111] Connection refused'))
unit-vault-b-2: 16:36:55 ERROR unit.vault-b/2.juju-log vault-autounseal-requires:2: [vault_client] Error while checking Vault health status: HTTPSConnectionPool(host='vault-b-2.vault-b-endpoints.test-autounseal-r8x0.svc.cluster.local', port=8200): Max retries exceeded with url: /v1/sys/health (Caused by NewConnectionError('<urllib3.connection.HTTPSConnection object at 0x7f9cd5db4080>: Failed to establish a new connection: [Errno 111] Connection refused'))
unit-vault-b-2: 16:36:57 ERROR unit.vault-b/2.juju-log vault-autounseal-requires:2: [vault_client] Error while checking Vault health status: HTTPSConnectionPool(host='vault-b-2.vault-b-endpoints.test-autounseal-r8x0.svc.cluster.local', port=8200): Max retries exceeded with url: /v1/sys/health (Caused by NewConnectionError('<urllib3.connection.HTTPSConnection object at 0x7ff435212ab0>: Failed to establish a new connection: [Errno 111] Connection refused'))
unit-vault-b-1: 16:36:57 ERROR unit.vault-b/1.juju-log vault-autounseal-requires:2: [vault_client] Error while checking Vault health status: HTTPSConnectionPool(host='vault-b-1.vault-b-endpoints.test-autounseal-r8x0.svc.cluster.local', port=8200): Max retries exceeded with url: /v1/sys/health (Caused by NewConnectionError('<urllib3.connection.HTTPSConnection object at 0x7f5a7d3caff0>: Failed to establish a new connection: [Errno 111] Connection refused'))
unit-vault-b-1: 16:36:59 ERROR unit.vault-b/1.juju-log vault-autounseal-requires:2: [vault_client] Error while checking Vault health status: HTTPSConnectionPool(host='vault-b-1.vault-b-endpoints.test-autounseal-r8x0.svc.cluster.local', port=8200): Max retries exceeded with url: /v1/sys/health (Caused by NewConnectionError('<urllib3.connection.HTTPSConnection object at 0x7fdca92c4710>: Failed to establish a new connection: [Errno 111] Connection refused'))
unit-vault-b-2: 16:36:59 ERROR unit.vault-b/2.juju-log vault-autounseal-requires:2: [vault_client] Error while checking Vault health status: HTTPSConnectionPool(host='vault-b-2.vault-b-endpoints.test-autounseal-r8x0.svc.cluster.local', port=8200): Max retries exceeded with url: /v1/sys/health (Caused by NewConnectionError('<urllib3.connection.HTTPSConnection object at 0x7f3ed73312b0>: Failed to establish a new connection: [Errno 111] Connection refused'))
unit-vault-b-2: 16:37:01 ERROR unit.vault-b/2.juju-log vault-autounseal-requires:2: [vault_client] Error while checking Vault health status: HTTPSConnectionPool(host='vault-b-2.vault-b-endpoints.test-autounseal-r8x0.svc.cluster.local', port=8200): Max retries exceeded with url: /v1/sys/health (Caused by NewConnectionError('<urllib3.connection.HTTPSConnection object at 0x7f7f829bed80>: Failed to establish a new connection: [Errno 111] Connection refused'))
unit-vault-b-1: 16:37:02 ERROR unit.vault-b/1.juju-log vault-autounseal-requires:2: [vault_client] Error while checking Vault health status: HTTPSConnectionPool(host='vault-b-1.vault-b-endpoints.test-autounseal-r8x0.svc.cluster.local', port=8200): Max retries exceeded with url: /v1/sys/health (Caused by NewConnectionError('<urllib3.connection.HTTPSConnection object at 0x7fb0a860e5a0>: Failed to establish a new connection: [Errno 111] Connection refused'))
unit-vault-b-2: 16:37:04 ERROR unit.vault-b/2.juju-log vault-peers:0: [vault_client] Error while checking Vault health status: HTTPSConnectionPool(host='vault-b-2.vault-b-endpoints.test-autounseal-r8x0.svc.cluster.local', port=8200): Max retries exceeded with url: /v1/sys/health (Caused by NewConnectionError('<urllib3.connection.HTTPSConnection object at 0x7f07ff3c0140>: Failed to establish a new connection: [Errno 111] Connection refused'))
unit-vault-b-1: 16:37:04 ERROR unit.vault-b/1.juju-log vault-peers:0: [vault_client] Error while checking Vault health status: HTTPSConnectionPool(host='vault-b-1.vault-b-endpoints.test-autounseal-r8x0.svc.cluster.local', port=8200): Max retries exceeded with url: /v1/sys/health (Caused by NewConnectionError('<urllib3.connection.HTTPSConnection object at 0x7fc0b3bc0140>: Failed to establish a new connection: [Errno 111] Connection refused'))
unit-vault-b-0: 16:37:46 ERROR unit.vault-b/0.juju-log [vault_client] Error while checking Vault health status: HTTPSConnectionPool(host='vault-b-0.vault-b-endpoints.test-autounseal-r8x0.svc.cluster.local', port=8200): Max retries exceeded with url: /v1/sys/health (Caused by NewConnectionError('<urllib3.connection.HTTPSConnection object at 0x7eff8079fce0>: Failed to establish a new connection: [Errno 111] Connection refused'))
unit-vault-b-2: 16:38:14 ERROR unit.vault-b/2.juju-log [vault_client] Error while checking Vault health status: HTTPSConnectionPool(host='vault-b-2.vault-b-endpoints.test-autounseal-r8x0.svc.cluster.local', port=8200): Max retries exceeded with url: /v1/sys/health (Caused by NewConnectionError('<urllib3.connection.HTTPSConnection object at 0x7f4f5c7b31d0>: Failed to establish a new connection: [Errno 111] Connection refused'))
unit-vault-b-1: 16:38:14 ERROR unit.vault-b/1.juju-log [vault_client] Error while checking Vault health status: HTTPSConnectionPool(host='vault-b-1.vault-b-endpoints.test-autounseal-r8x0.svc.cluster.local', port=8200): Max retries exceeded with url: /v1/sys/health (Caused by NewConnectionError('<urllib3.connection.HTTPSConnection object at 0x7f6eaebaad20>: Failed to establish a new connection: [Errno 111] Connection refused'))
unit-vault-b-0: 16:38:15 ERROR unit.vault-b/0.juju-log [vault_client] Error while checking Vault health status: HTTPSConnectionPool(host='vault-b-0.vault-b-endpoints.test-autounseal-r8x0.svc.cluster.local', port=8200): Max retries exceeded with url: /v1/sys/health (Caused by NewConnectionError('<urllib3.connection.HTTPSConnection object at 0x7fee65fb2cc0>: Failed to establish a new connection: [Errno 111] Connection refused'))
model-745f742b-b6c7-4659-8ffc-94b5ce0d9868: 16:38:19 ERROR juju.worker.dependency "log-sender" manifold worker returned unexpected error: sending log message: websocket: close 1005 (no status): websocket: close sent
unit-vault-k8s-2: 16:38:22 ERROR juju.worker.dependency "log-sender" manifold worker returned unexpected error: sending log message: websocket: close 1005 (no status): websocket: close sent
unit-vault-b-2: 16:38:25 ERROR juju.worker.dependency "log-sender" manifold worker returned unexpected error: sending log message: websocket: close 1005 (no status): websocket: close sent
unit-vault-b-1: 16:38:25 ERROR juju.worker.dependency "log-sender" manifold worker returned unexpected error: sending log message: websocket: close 1005 (no status): websocket: close sent
unit-vault-b-0: 16:38:25 ERROR juju.worker.dependency "log-sender" manifold worker returned unexpected error: sending log message: websocket: close 1005 (no status): websocket: close sent
unit-vault-k8s-0: 16:38:28 ERROR juju.worker.dependency "log-sender" manifold worker returned unexpected error: sending log message: websocket: close 1005 (no status): websocket: close sent
unit-vault-k8s-1: 16:38:29 ERROR juju.worker.dependency "log-sender" manifold worker returned unexpected error: sending log message: websocket: close 1005 (no status): websocket: close sent

[32mINFO    [0m pytest_operator.plugin:plugin.py:1063 Resetting model test-autounseal-r8x0...
[32mINFO    [0m pytest_operator.plugin:plugin.py:1052    Destroying applications vault-b
[32mINFO    [0m pytest_operator.plugin:plugin.py:1052    Destroying applications vault-k8s
[32mINFO    [0m pytest_operator.plugin:plugin.py:1068 Not waiting on reset to complete.
[32mINFO    [0m pytest_operator.plugin:plugin.py:1039 Forgetting model main...