[32mINFO    [0m juju.model:__init__.py:3254 Waiting for model:
  vault-k8s/0 [executing] active: 
  vault-k8s/1 [executing] active: 
  vault-k8s/2 [executing] active: 
[32mINFO    [0m juju.model:__init__.py:3254 Waiting for model:
  tls-certificates-requirer/0 [executing] active: Certificate relation is created
[32mINFO    [0m pytest_operator.plugin:plugin.py:937 Model status:

Model          Controller                Cloud/Region        Version  SLA          Timestamp
test-pki-3naq  github-pr-36040-microk8s  microk8s/localhost  3.6.9    unsupported  12:25:26Z

App                        Version  Status  Scale  Charm                      Channel        Rev  Address         Exposed  Message
self-signed-certificates            active      1  self-signed-certificates   1/stable       317  10.152.183.204  no       
tls-certificates-requirer           active      1  tls-certificates-requirer  latest/stable   93  10.152.183.188  no       Unit certificate is available
vault-k8s                           active      3  vault-k8s                                   0  10.152.183.212  no       

Unit                          Workload  Agent  Address      Ports  Message
self-signed-certificates/0*   active    idle   10.1.242.83         
tls-certificates-requirer/0*  active    idle   10.1.242.88         Unit certificate is available
vault-k8s/0*                  active    idle   10.1.242.81         
vault-k8s/1                   active    idle   10.1.242.89         
vault-k8s/2                   active    idle   10.1.242.90         

[32mINFO    [0m pytest_operator.plugin:plugin.py:943 Juju error logs:

unit-vault-k8s-1: 12:23:38 ERROR unit.vault-k8s/1.juju-log [vault_client] Error while checking Vault health status: HTTPSConnectionPool(host='vault-k8s-1.vault-k8s-endpoints.test-pki-3naq.svc.cluster.local', port=8200): Max retries exceeded with url: /v1/sys/health (Caused by NewConnectionError('<urllib3.connection.HTTPSConnection object at 0x7effe69ac9e0>: Failed to establish a new connection: [Errno 111] Connection refused'))
unit-vault-k8s-1: 12:23:40 ERROR unit.vault-k8s/1.juju-log [vault_client] Error while checking Vault health status: HTTPSConnectionPool(host='vault-k8s-1.vault-k8s-endpoints.test-pki-3naq.svc.cluster.local', port=8200): Max retries exceeded with url: /v1/sys/health (Caused by NewConnectionError('<urllib3.connection.HTTPSConnection object at 0x7fa90d6fa4b0>: Failed to establish a new connection: [Errno 111] Connection refused'))
unit-vault-k8s-2: 12:23:40 ERROR unit.vault-k8s/2.juju-log [vault_client] Error while checking Vault health status: HTTPSConnectionPool(host='vault-k8s-2.vault-k8s-endpoints.test-pki-3naq.svc.cluster.local', port=8200): Max retries exceeded with url: /v1/sys/health (Caused by NewConnectionError('<urllib3.connection.HTTPSConnection object at 0x7fcf0ea58590>: Failed to establish a new connection: [Errno 111] Connection refused'))
unit-vault-k8s-1: 12:23:41 ERROR unit.vault-k8s/1.juju-log vault-peers:0: [vault_client] Error while checking Vault health status: HTTPSConnectionPool(host='vault-k8s-1.vault-k8s-endpoints.test-pki-3naq.svc.cluster.local', port=8200): Max retries exceeded with url: /v1/sys/health (Caused by NewConnectionError('<urllib3.connection.HTTPSConnection object at 0x7f62d66dc590>: Failed to establish a new connection: [Errno 111] Connection refused'))
unit-vault-k8s-2: 12:23:41 ERROR unit.vault-k8s/2.juju-log [vault_client] Error while checking Vault health status: HTTPSConnectionPool(host='vault-k8s-2.vault-k8s-endpoints.test-pki-3naq.svc.cluster.local', port=8200): Max retries exceeded with url: /v1/sys/health (Caused by NewConnectionError('<urllib3.connection.HTTPSConnection object at 0x7f37ae330050>: Failed to establish a new connection: [Errno 111] Connection refused'))
unit-vault-k8s-2: 12:23:43 ERROR unit.vault-k8s/2.juju-log vault-peers:0: [vault_client] Error while checking Vault health status: HTTPSConnectionPool(host='vault-k8s-2.vault-k8s-endpoints.test-pki-3naq.svc.cluster.local', port=8200): Max retries exceeded with url: /v1/sys/health (Caused by NewConnectionError('<urllib3.connection.HTTPSConnection object at 0x7f486c5304a0>: Failed to establish a new connection: [Errno 111] Connection refused'))
unit-self-signed-certificates-0: 12:24:33 ERROR unit.self-signed-certificates/0.juju-log At least 1 matching relation ID not found with the relation name 'send-ca-cert'
unit-self-signed-certificates-0: 12:24:41 ERROR unit.self-signed-certificates/0.juju-log certificates:1: At least 1 matching relation ID not found with the relation name 'send-ca-cert'
unit-self-signed-certificates-0: 12:24:43 ERROR unit.self-signed-certificates/0.juju-log certificates:1: At least 1 matching relation ID not found with the relation name 'send-ca-cert'
unit-self-signed-certificates-0: 12:24:45 ERROR unit.self-signed-certificates/0.juju-log certificates:1: At least 1 matching relation ID not found with the relation name 'send-ca-cert'
unit-self-signed-certificates-0: 12:24:48 ERROR unit.self-signed-certificates/0.juju-log certificates:1: At least 1 matching relation ID not found with the relation name 'send-ca-cert'
unit-self-signed-certificates-0: 12:24:53 ERROR unit.self-signed-certificates/0.juju-log At least 1 matching relation ID not found with the relation name 'send-ca-cert'
unit-self-signed-certificates-0: 12:25:19 ERROR unit.self-signed-certificates/0.juju-log certificates:1: At least 1 matching relation ID not found with the relation name 'send-ca-cert'

[32mINFO    [0m pytest_operator.plugin:plugin.py:1049 Resetting model test-pki-3naq...
[32mINFO    [0m pytest_operator.plugin:plugin.py:1038    Destroying applications vault-k8s
[32mINFO    [0m pytest_operator.plugin:plugin.py:1038    Destroying applications self-signed-certificates
[32mINFO    [0m pytest_operator.plugin:plugin.py:1038    Destroying applications tls-certificates-requirer
[32mINFO    [0m pytest_operator.plugin:plugin.py:1054 Not waiting on reset to complete.
[32mINFO    [0m pytest_operator.plugin:plugin.py:1025 Forgetting model main...