[32mINFO    [0m juju.model:__init__.py:2301 Deploying local:vault-kv-requirer-1
[32mINFO    [0m juju.model:__init__.py:3254 Waiting for model:
  vault-kv-requirer-b/0 [allocating] waiting: installing agent
[32mINFO    [0m juju.model:__init__.py:3254 Waiting for model:
  vault-kv-requirer-b/0 [idle] active: 
[32mINFO    [0m juju.model:__init__.py:3254 Waiting for model:
  vault-k8s/0 [idle] active: 
  vault-k8s/1 [idle] active: 
  vault-k8s/2 [idle] active: 
  vault-kv-requirer-b/0 [idle] active: 
[32mINFO    [0m juju.model:__init__.py:3254 Waiting for model:
  vault-kv-requirer-b/0 [idle] active:
[32mINFO    [0m pytest_operator.plugin:plugin.py:937 Model status:

Model         Controller                Cloud/Region        Version  SLA          Timestamp
test-kv-uxsq  github-pr-048bc-microk8s  microk8s/localhost  3.6.8    unsupported  14:42:31Z

App                  Version  Status  Scale  Charm              Channel  Rev  Address         Exposed  Message
vault-k8s                     active      3  vault-k8s                     0  10.152.183.28   no       
vault-kv-requirer-a           active      1  vault-kv-requirer             0  10.152.183.240  no       
vault-kv-requirer-b           active      1  vault-kv-requirer             1  10.152.183.99   no       

Unit                    Workload  Agent  Address      Ports  Message
vault-k8s/0*            active    idle   10.1.63.208         
vault-k8s/1             active    idle   10.1.63.217         
vault-k8s/2             active    idle   10.1.63.216         
vault-kv-requirer-a/0*  active    idle   10.1.63.219         
vault-kv-requirer-b/0*  active    idle   10.1.63.221         

[32mINFO    [0m pytest_operator.plugin:plugin.py:943 Juju error logs:

unit-vault-k8s-2: 14:38:46 ERROR unit.vault-k8s/2.juju-log [vault_client] Error while checking Vault health status: HTTPSConnectionPool(host='vault-k8s-2.vault-k8s-endpoints.test-kv-uxsq.svc.cluster.local', port=8200): Max retries exceeded with url: /v1/sys/health (Caused by NewConnectionError('<urllib3.connection.HTTPSConnection object at 0x7f6bf8557740>: Failed to establish a new connection: [Errno 111] Connection refused'))
unit-vault-k8s-1: 14:38:47 ERROR unit.vault-k8s/1.juju-log [vault_client] Error while checking Vault health status: HTTPSConnectionPool(host='vault-k8s-1.vault-k8s-endpoints.test-kv-uxsq.svc.cluster.local', port=8200): Max retries exceeded with url: /v1/sys/health (Caused by NewConnectionError('<urllib3.connection.HTTPSConnection object at 0x7f024ca575c0>: Failed to establish a new connection: [Errno 111] Connection refused'))
unit-vault-k8s-2: 14:38:47 ERROR unit.vault-k8s/2.juju-log [vault_client] Error while checking Vault health status: HTTPSConnectionPool(host='vault-k8s-2.vault-k8s-endpoints.test-kv-uxsq.svc.cluster.local', port=8200): Max retries exceeded with url: /v1/sys/health (Caused by NewConnectionError('<urllib3.connection.HTTPSConnection object at 0x7f671193b020>: Failed to establish a new connection: [Errno 111] Connection refused'))
unit-vault-k8s-1: 14:38:48 ERROR unit.vault-k8s/1.juju-log [vault_client] Error while checking Vault health status: HTTPSConnectionPool(host='vault-k8s-1.vault-k8s-endpoints.test-kv-uxsq.svc.cluster.local', port=8200): Max retries exceeded with url: /v1/sys/health (Caused by NewConnectionError('<urllib3.connection.HTTPSConnection object at 0x7efff17370e0>: Failed to establish a new connection: [Errno 111] Connection refused'))
unit-vault-k8s-2: 14:38:49 ERROR unit.vault-k8s/2.juju-log vault-peers:0: [vault_client] Error while checking Vault health status: HTTPSConnectionPool(host='vault-k8s-2.vault-k8s-endpoints.test-kv-uxsq.svc.cluster.local', port=8200): Max retries exceeded with url: /v1/sys/health (Caused by NewConnectionError('<urllib3.connection.HTTPSConnection object at 0x7f2ac393afc0>: Failed to establish a new connection: [Errno 111] Connection refused'))
unit-vault-k8s-1: 14:38:49 ERROR unit.vault-k8s/1.juju-log vault-peers:0: [vault_client] Error while checking Vault health status: HTTPSConnectionPool(host='vault-k8s-1.vault-k8s-endpoints.test-kv-uxsq.svc.cluster.local', port=8200): Max retries exceeded with url: /v1/sys/health (Caused by NewConnectionError('<urllib3.connection.HTTPSConnection object at 0x7fdd9ebff110>: Failed to establish a new connection: [Errno 111] Connection refused'))
unit-vault-k8s-2: 14:41:19 ERROR juju.worker.dependency "log-sender" manifold worker returned unexpected error: sending log message: websocket: close 1005 (no status): websocket: close sent
unit-vault-k8s-1: 14:41:19 ERROR juju.worker.dependency "log-sender" manifold worker returned unexpected error: sending log message: websocket: close 1005 (no status): websocket: close sent
model-40b0fc2b-8234-434d-84e5-c0657afc4ce5: 14:41:20 ERROR juju.worker.dependency "log-sender" manifold worker returned unexpected error: sending log message: websocket: close 1005 (no status): websocket: close sent
unit-vault-k8s-0: 14:41:23 ERROR juju.worker.dependency "log-sender" manifold worker returned unexpected error: sending log message: websocket: close 1005 (no status): websocket: close sent
unit-vault-k8s-1: 14:42:00 ERROR juju.worker.dependency "log-sender" manifold worker returned unexpected error: sending log message: websocket: close 1005 (no status): websocket: close sent
unit-vault-k8s-2: 14:42:01 ERROR juju.worker.dependency "log-sender" manifold worker returned unexpected error: sending log message: websocket: close 1005 (no status): websocket: close sent
model-40b0fc2b-8234-434d-84e5-c0657afc4ce5: 14:42:01 ERROR juju.worker.dependency "log-sender" manifold worker returned unexpected error: sending log message: websocket: close 1005 (no status): websocket: close sent

[32mINFO    [0m pytest_operator.plugin:plugin.py:1049 Resetting model test-kv-uxsq...
[32mINFO    [0m pytest_operator.plugin:plugin.py:1038    Destroying applications vault-k8s
[32mINFO    [0m pytest_operator.plugin:plugin.py:1038    Destroying applications vault-kv-requirer-a
[32mINFO    [0m pytest_operator.plugin:plugin.py:1038    Destroying applications vault-kv-requirer-b
[32mINFO    [0m pytest_operator.plugin:plugin.py:1054 Not waiting on reset to complete.
[32mINFO    [0m pytest_operator.plugin:plugin.py:1025 Forgetting model main...