[32mINFO    [0m juju.model:__init__.py:3254 Waiting for model:
  vault-k8s/0 [executing] active: 
  vault-k8s/1 [executing] active: 
  vault-k8s/2 [executing] active: 
[32mINFO    [0m juju.model:__init__.py:3254 Waiting for model:
  tls-certificates-requirer/0 [executing] active: Certificate relation is created
[32mINFO    [0m pytest_operator.plugin:plugin.py:937 Model status:

Model          Controller                Cloud/Region        Version  SLA          Timestamp
test-pki-4gh9  github-pr-b0171-microk8s  microk8s/localhost  3.6.8    unsupported  11:21:09Z

App                        Version  Status  Scale  Charm                      Channel        Rev  Address         Exposed  Message
self-signed-certificates            active      1  self-signed-certificates   1/stable       317  10.152.183.181  no       
tls-certificates-requirer           active      1  tls-certificates-requirer  latest/stable   93  10.152.183.214  no       Unit certificate is available
vault-k8s                           active      3  vault-k8s                                   0  10.152.183.30   no       

Unit                          Workload  Agent  Address       Ports  Message
self-signed-certificates/0*   active    idle   10.1.169.147         
tls-certificates-requirer/0*  active    idle   10.1.169.149         Unit certificate is available
vault-k8s/0*                  active    idle   10.1.169.152         
vault-k8s/1                   active    idle   10.1.169.154         
vault-k8s/2                   active    idle   10.1.169.153         

[32mINFO    [0m pytest_operator.plugin:plugin.py:943 Juju error logs:

unit-vault-k8s-1: 11:15:18 ERROR unit.vault-k8s/1.juju-log [vault_client] Error while checking Vault health status: HTTPSConnectionPool(host='vault-k8s-1.vault-k8s-endpoints.test-pki-4gh9.svc.cluster.local', port=8200): Max retries exceeded with url: /v1/sys/health (Caused by NewConnectionError('<urllib3.connection.HTTPSConnection object at 0x7fb98c7af710>: Failed to establish a new connection: [Errno 111] Connection refused'))
unit-vault-k8s-1: 11:15:20 ERROR unit.vault-k8s/1.juju-log [vault_client] Error while checking Vault health status: HTTPSConnectionPool(host='vault-k8s-1.vault-k8s-endpoints.test-pki-4gh9.svc.cluster.local', port=8200): Max retries exceeded with url: /v1/sys/health (Caused by NewConnectionError('<urllib3.connection.HTTPSConnection object at 0x7f657a5fb080>: Failed to establish a new connection: [Errno 111] Connection refused'))
unit-vault-k8s-1: 11:15:21 ERROR unit.vault-k8s/1.juju-log vault-peers:0: [vault_client] Error while checking Vault health status: HTTPSConnectionPool(host='vault-k8s-1.vault-k8s-endpoints.test-pki-4gh9.svc.cluster.local', port=8200): Max retries exceeded with url: /v1/sys/health (Caused by NewConnectionError('<urllib3.connection.HTTPSConnection object at 0x7feae2737260>: Failed to establish a new connection: [Errno 111] Connection refused'))
unit-self-signed-certificates-0: 11:19:33 ERROR unit.self-signed-certificates/0.juju-log At least 1 matching relation ID not found with the relation name 'send-ca-cert'
unit-self-signed-certificates-0: 11:20:13 ERROR unit.self-signed-certificates/0.juju-log At least 1 matching relation ID not found with the relation name 'send-ca-cert'
unit-self-signed-certificates-0: 11:20:22 ERROR unit.self-signed-certificates/0.juju-log certificates:1: At least 1 matching relation ID not found with the relation name 'send-ca-cert'
unit-self-signed-certificates-0: 11:20:23 ERROR unit.self-signed-certificates/0.juju-log certificates:1: At least 1 matching relation ID not found with the relation name 'send-ca-cert'
unit-self-signed-certificates-0: 11:20:26 ERROR unit.self-signed-certificates/0.juju-log certificates:1: At least 1 matching relation ID not found with the relation name 'send-ca-cert'
unit-self-signed-certificates-0: 11:20:29 ERROR unit.self-signed-certificates/0.juju-log certificates:1: At least 1 matching relation ID not found with the relation name 'send-ca-cert'
unit-self-signed-certificates-0: 11:20:39 ERROR unit.self-signed-certificates/0.juju-log At least 1 matching relation ID not found with the relation name 'send-ca-cert'
unit-self-signed-certificates-0: 11:21:01 ERROR unit.self-signed-certificates/0.juju-log certificates:1: At least 1 matching relation ID not found with the relation name 'send-ca-cert'

[32mINFO    [0m pytest_operator.plugin:plugin.py:1049 Resetting model test-pki-4gh9...
[32mINFO    [0m pytest_operator.plugin:plugin.py:1038    Destroying applications vault-k8s
[32mINFO    [0m pytest_operator.plugin:plugin.py:1038    Destroying applications self-signed-certificates
[32mINFO    [0m pytest_operator.plugin:plugin.py:1038    Destroying applications tls-certificates-requirer
[32mINFO    [0m pytest_operator.plugin:plugin.py:1054 Not waiting on reset to complete.
[32mINFO    [0m pytest_operator.plugin:plugin.py:1025 Forgetting model main...