[32mINFO    [0m juju.model:__init__.py:3254 Waiting for model:
  vault-k8s/0 [idle] active: 
  vault-k8s/1 [idle] active: 
  vault-k8s/2 [idle] active: 
[32mINFO    [0m juju.model:__init__.py:3254 Waiting for model:
  s3-integrator/0 [idle] active:
[32mINFO    [0m pytest_operator.plugin:plugin.py:951 Model status:

Model             Controller                Cloud/Region        Version  SLA          Timestamp
test-backup-iu3d  github-pr-727e9-microk8s  microk8s/localhost  3.6.8    unsupported  12:30:47Z

App            Version                Status  Scale  Charm          Channel         Rev  Address         Exposed  Message
minio          res:oci-image@220b31a  active      1  minio          ckf-1.9/stable  383  10.152.183.119  no       
s3-integrator                         active      1  s3-integrator  latest/stable   145  10.152.183.71   no       
vault-k8s                             active      3  vault-k8s                        0  10.152.183.174  no       

Unit              Workload  Agent  Address      Ports          Message
minio/0*          active    idle   10.1.52.220  9000-9001/TCP  
s3-integrator/0*  active    idle   10.1.52.214                 
vault-k8s/0*      active    idle   10.1.52.208                 
vault-k8s/1       active    idle   10.1.52.218                 
vault-k8s/2       active    idle   10.1.52.217                 

[32mINFO    [0m pytest_operator.plugin:plugin.py:957 Juju error logs:

unit-vault-k8s-2: 12:27:58 ERROR unit.vault-k8s/2.juju-log [vault_client] Error while checking Vault health status: HTTPSConnectionPool(host='vault-k8s-2.vault-k8s-endpoints.test-backup-iu3d.svc.cluster.local', port=8200): Max retries exceeded with url: /v1/sys/health (Caused by NewConnectionError('<urllib3.connection.HTTPSConnection object at 0x7f1648f622d0>: Failed to establish a new connection: [Errno 111] Connection refused'))
unit-vault-k8s-1: 12:28:00 ERROR unit.vault-k8s/1.juju-log [vault_client] Error while checking Vault health status: HTTPSConnectionPool(host='vault-k8s-1.vault-k8s-endpoints.test-backup-iu3d.svc.cluster.local', port=8200): Max retries exceeded with url: /v1/sys/health (Caused by NewConnectionError('<urllib3.connection.HTTPSConnection object at 0x7f1dd2962270>: Failed to establish a new connection: [Errno 111] Connection refused'))
unit-vault-k8s-2: 12:28:01 ERROR unit.vault-k8s/2.juju-log [vault_client] Error while checking Vault health status: HTTPSConnectionPool(host='vault-k8s-2.vault-k8s-endpoints.test-backup-iu3d.svc.cluster.local', port=8200): Max retries exceeded with url: /v1/sys/health (Caused by NewConnectionError('<urllib3.connection.HTTPSConnection object at 0x7f005d2d48c0>: Failed to establish a new connection: [Errno 111] Connection refused'))
unit-vault-k8s-1: 12:28:03 ERROR unit.vault-k8s/1.juju-log [vault_client] Error while checking Vault health status: HTTPSConnectionPool(host='vault-k8s-1.vault-k8s-endpoints.test-backup-iu3d.svc.cluster.local', port=8200): Max retries exceeded with url: /v1/sys/health (Caused by NewConnectionError('<urllib3.connection.HTTPSConnection object at 0x7f99a3634b30>: Failed to establish a new connection: [Errno 111] Connection refused'))
unit-vault-k8s-2: 12:28:04 ERROR unit.vault-k8s/2.juju-log vault-peers:0: [vault_client] Error while checking Vault health status: HTTPSConnectionPool(host='vault-k8s-2.vault-k8s-endpoints.test-backup-iu3d.svc.cluster.local', port=8200): Max retries exceeded with url: /v1/sys/health (Caused by NewConnectionError('<urllib3.connection.HTTPSConnection object at 0x7fe563be4c50>: Failed to establish a new connection: [Errno 111] Connection refused'))
unit-vault-k8s-1: 12:28:05 ERROR unit.vault-k8s/1.juju-log vault-peers:0: [vault_client] Error while checking Vault health status: HTTPSConnectionPool(host='vault-k8s-1.vault-k8s-endpoints.test-backup-iu3d.svc.cluster.local', port=8200): Max retries exceeded with url: /v1/sys/health (Caused by NewConnectionError('<urllib3.connection.HTTPSConnection object at 0x7f1194fa1c10>: Failed to establish a new connection: [Errno 111] Connection refused'))

[32mINFO    [0m pytest_operator.plugin:plugin.py:1063 Resetting model test-backup-iu3d...
[32mINFO    [0m pytest_operator.plugin:plugin.py:1052    Destroying applications vault-k8s
[32mINFO    [0m pytest_operator.plugin:plugin.py:1052    Destroying applications s3-integrator
[32mINFO    [0m pytest_operator.plugin:plugin.py:1052    Destroying applications minio
[32mINFO    [0m pytest_operator.plugin:plugin.py:1068 Not waiting on reset to complete.
[32mINFO    [0m pytest_operator.plugin:plugin.py:1039 Forgetting model main...