[32mINFO    [0m pytest_operator.plugin:plugin.py:929 Model status:

Model                  Controller                Cloud/Region        Version  SLA          Timestamp
test-integration-uab3  github-pr-4cb92-microk8s  microk8s/localhost  3.6.1    unsupported  00:12:19Z

App        Version  Status  Scale  Charm      Channel  Rev  Address        Exposed  Message
vault-k8s           error       3  vault-k8s             0  10.152.183.43  no       hook failed: "config-changed"

Unit          Workload  Agent      Address     Ports  Message
vault-k8s/0*  error     idle       10.1.53.16         hook failed: "config-changed"
vault-k8s/1   waiting   executing  10.1.53.24         Waiting for CA certificate to be accessible in the charm
vault-k8s/2   waiting   executing  10.1.53.22         (start) Waiting for CA certificate to be accessible in the charm

[32mINFO    [0m pytest_operator.plugin:plugin.py:935 Juju error logs:

unit-vault-k8s-0: 00:12:18 ERROR unit.vault-k8s/0.juju-log Uncaught exception while in charm code:
Traceback (most recent call last):
  File "/var/lib/juju/agents/unit-vault-k8s-0/charm/./src/charm.py", line 806, in <module>
    main(VaultCharm)
  File "/var/lib/juju/agents/unit-vault-k8s-0/charm/venv/ops/__init__.py", line 343, in __call__
    return _main.main(charm_class=charm_class, use_juju_for_storage=use_juju_for_storage)
  File "/var/lib/juju/agents/unit-vault-k8s-0/charm/venv/ops/_main.py", line 543, in main
    manager.run()
  File "/var/lib/juju/agents/unit-vault-k8s-0/charm/venv/ops/_main.py", line 529, in run
    self._emit()
  File "/var/lib/juju/agents/unit-vault-k8s-0/charm/venv/ops/_main.py", line 518, in _emit
    _emit_charm_event(self.charm, self.dispatcher.event_name, self._juju_context)
  File "/var/lib/juju/agents/unit-vault-k8s-0/charm/venv/ops/_main.py", line 134, in _emit_charm_event
    event_to_emit.emit(*args, **kwargs)
  File "/var/lib/juju/agents/unit-vault-k8s-0/charm/venv/ops/framework.py", line 347, in emit
    framework._emit(event)
  File "/var/lib/juju/agents/unit-vault-k8s-0/charm/venv/ops/framework.py", line 857, in _emit
    self._reemit(event_path)
  File "/var/lib/juju/agents/unit-vault-k8s-0/charm/venv/ops/framework.py", line 947, in _reemit
    custom_handler(event)
  File "/var/lib/juju/agents/unit-vault-k8s-0/charm/lib/charms/tempo_coordinator_k8s/v0/charm_tracing.py", line 1064, in wrapped_function
    return callable(*args, **kwargs)  # type: ignore
  File "/var/lib/juju/agents/unit-vault-k8s-0/charm/./src/charm.py", line 310, in _configure
    self._set_pebble_plan()
  File "/var/lib/juju/agents/unit-vault-k8s-0/charm/lib/charms/tempo_coordinator_k8s/v0/charm_tracing.py", line 1064, in wrapped_function
    return callable(*args, **kwargs)  # type: ignore
  File "/var/lib/juju/agents/unit-vault-k8s-0/charm/./src/charm.py", line 710, in _set_pebble_plan
    self._container.replan()
  File "/var/lib/juju/agents/unit-vault-k8s-0/charm/venv/ops/model.py", line 2381, in replan
    self._pebble.replan_services()
  File "/var/lib/juju/agents/unit-vault-k8s-0/charm/venv/ops/pebble.py", line 2144, in replan_services
    return self._services_action('replan', [], timeout, delay)
  File "/var/lib/juju/agents/unit-vault-k8s-0/charm/venv/ops/pebble.py", line 2244, in _services_action
    raise ChangeError(change.err, change)
ops.pebble.ChangeError: cannot perform the following tasks:
- Start service "vault" (service start attempt: exited quickly with code 1, will restart)
----- Logs from task 1 -----
2025-01-15T00:12:18Z INFO Most recent service output:
    error loading configuration from /vault/config/config.hcl: stat /vault/config/config.hcl: no such file or directory
    error loading configuration from /vault/config/vault.hcl: stat /vault/config/vault.hcl: no such file or directory
2025-01-15T00:12:18Z ERROR service start attempt: exited quickly with code 1, will restart
-----
unit-vault-k8s-0: 00:12:18 ERROR juju.worker.uniter.operation hook "config-changed" (via hook dispatching script: dispatch) failed: exit status 1

[32mINFO    [0m pytest_operator.plugin:plugin.py:949 juju-crashdump finished [0]
[32mINFO    [0m pytest_operator.plugin:plugin.py:1041 Resetting model test-integration-uab3...
[32mINFO    [0m pytest_operator.plugin:plugin.py:1030    Destroying applications vault-k8s
[32mINFO    [0m pytest_operator.plugin:plugin.py:1046 Not waiting on reset to complete.
[32mINFO    [0m pytest_operator.plugin:plugin.py:1017 Forgetting model main...