[32mINFO    [0m juju.model:__init__.py:3254 Waiting for model:
  vault-k8s/0 [idle] active: 
  vault-k8s/1 [idle] active: 
  vault-k8s/2 [idle] active: 
[32mINFO    [0m juju.model:__init__.py:3254 Waiting for model:
  s3-integrator/0 [idle] active:
[32mINFO    [0m pytest_operator.plugin:plugin.py:937 Model status:

Model             Controller                Cloud/Region        Version  SLA          Timestamp
test-backup-0mzc  github-pr-738b4-microk8s  microk8s/localhost  3.6.8    unsupported  07:40:06Z

App            Version                Status  Scale  Charm          Channel         Rev  Address         Exposed  Message
minio          res:oci-image@220b31a  active      1  minio          ckf-1.9/stable  383  10.152.183.79   no       
s3-integrator                         active      1  s3-integrator  latest/stable   145  10.152.183.177  no       
vault-k8s                             active      3  vault-k8s                        0  10.152.183.185  no       

Unit              Workload  Agent  Address      Ports          Message
minio/0*          active    idle   10.1.63.220  9000-9001/TCP  
s3-integrator/0*  active    idle   10.1.63.214                 
vault-k8s/0*      active    idle   10.1.63.208                 
vault-k8s/1       active    idle   10.1.63.217                 
vault-k8s/2       active    idle   10.1.63.218                 

[32mINFO    [0m pytest_operator.plugin:plugin.py:943 Juju error logs:

unit-vault-k8s-2: 07:37:29 ERROR unit.vault-k8s/2.juju-log [vault_client] Error while checking Vault health status: HTTPSConnectionPool(host='vault-k8s-2.vault-k8s-endpoints.test-backup-0mzc.svc.cluster.local', port=8200): Max retries exceeded with url: /v1/sys/health (Caused by NewConnectionError('<urllib3.connection.HTTPSConnection object at 0x7facb9158a70>: Failed to establish a new connection: [Errno 111] Connection refused'))
unit-vault-k8s-1: 07:37:29 ERROR unit.vault-k8s/1.juju-log [vault_client] Error while checking Vault health status: HTTPSConnectionPool(host='vault-k8s-1.vault-k8s-endpoints.test-backup-0mzc.svc.cluster.local', port=8200): Max retries exceeded with url: /v1/sys/health (Caused by NewConnectionError('<urllib3.connection.HTTPSConnection object at 0x7f2390c6c9e0>: Failed to establish a new connection: [Errno 111] Connection refused'))
unit-vault-k8s-2: 07:37:31 ERROR unit.vault-k8s/2.juju-log [vault_client] Error while checking Vault health status: HTTPSConnectionPool(host='vault-k8s-2.vault-k8s-endpoints.test-backup-0mzc.svc.cluster.local', port=8200): Max retries exceeded with url: /v1/sys/health (Caused by NewConnectionError('<urllib3.connection.HTTPSConnection object at 0x7fb9f2330950>: Failed to establish a new connection: [Errno 111] Connection refused'))
unit-vault-k8s-1: 07:37:31 ERROR unit.vault-k8s/1.juju-log [vault_client] Error while checking Vault health status: HTTPSConnectionPool(host='vault-k8s-1.vault-k8s-endpoints.test-backup-0mzc.svc.cluster.local', port=8200): Max retries exceeded with url: /v1/sys/health (Caused by NewConnectionError('<urllib3.connection.HTTPSConnection object at 0x7f99c42dc3b0>: Failed to establish a new connection: [Errno 111] Connection refused'))
unit-vault-k8s-2: 07:37:33 ERROR unit.vault-k8s/2.juju-log vault-peers:0: [vault_client] Error while checking Vault health status: HTTPSConnectionPool(host='vault-k8s-2.vault-k8s-endpoints.test-backup-0mzc.svc.cluster.local', port=8200): Max retries exceeded with url: /v1/sys/health (Caused by NewConnectionError('<urllib3.connection.HTTPSConnection object at 0x7fb2ba1308c0>: Failed to establish a new connection: [Errno 111] Connection refused'))
unit-vault-k8s-1: 07:37:33 ERROR unit.vault-k8s/1.juju-log vault-peers:0: [vault_client] Error while checking Vault health status: HTTPSConnectionPool(host='vault-k8s-1.vault-k8s-endpoints.test-backup-0mzc.svc.cluster.local', port=8200): Max retries exceeded with url: /v1/sys/health (Caused by NewConnectionError('<urllib3.connection.HTTPSConnection object at 0x7f0db8cdc5c0>: Failed to establish a new connection: [Errno 111] Connection refused'))

[32mINFO    [0m pytest_operator.plugin:plugin.py:1049 Resetting model test-backup-0mzc...
[32mINFO    [0m pytest_operator.plugin:plugin.py:1038    Destroying applications vault-k8s
[32mINFO    [0m pytest_operator.plugin:plugin.py:1038    Destroying applications s3-integrator
[32mINFO    [0m pytest_operator.plugin:plugin.py:1038    Destroying applications minio
[32mINFO    [0m pytest_operator.plugin:plugin.py:1054 Not waiting on reset to complete.
[32mINFO    [0m pytest_operator.plugin:plugin.py:1025 Forgetting model main...