[32mINFO    [0m juju.model:__init__.py:3254 Waiting for model:
  vault-b/0 [idle] active: 
  vault-b/1 [idle] active: 
  vault-b/2 [idle] active: 
[32mINFO    [0m juju.model:__init__.py:3254 Waiting for model:
  vault-b/0 [idle] active: 
  vault-b/1 [idle] active: 
  vault-b/2 [idle] active:
[32mINFO    [0m pytest_operator.plugin:plugin.py:951 Model status:

Model                 Controller                Cloud/Region        Version  SLA          Timestamp
test-autounseal-ful6  github-pr-cad1a-microk8s  microk8s/localhost  3.6.9    unsupported  21:39:56Z

App        Version  Status  Scale  Charm      Channel  Rev  Address         Exposed  Message
vault-b             active      3  vault-k8s             0  10.152.183.161  no       
vault-k8s           active      3  vault-k8s             1  10.152.183.235  no       

Unit          Workload  Agent  Address    Ports  Message
vault-b/0*    active    idle   10.1.7.42         
vault-b/1     active    idle   10.1.7.40         
vault-b/2     active    idle   10.1.7.41         
vault-k8s/0*  active    idle   10.1.7.21         
vault-k8s/1   active    idle   10.1.7.29         
vault-k8s/2   active    idle   10.1.7.28         

[32mINFO    [0m pytest_operator.plugin:plugin.py:957 Juju error logs:

unit-vault-k8s-2: 21:33:41 ERROR unit.vault-k8s/2.juju-log [vault_client] Error while checking Vault health status: HTTPSConnectionPool(host='vault-k8s-2.vault-k8s-endpoints.test-autounseal-ful6.svc.cluster.local', port=8200): Max retries exceeded with url: /v1/sys/health (Caused by NewConnectionError('<urllib3.connection.HTTPSConnection object at 0x7f616c436690>: Failed to establish a new connection: [Errno 111] Connection refused'))
unit-vault-k8s-2: 21:33:43 ERROR unit.vault-k8s/2.juju-log [vault_client] Error while checking Vault health status: HTTPSConnectionPool(host='vault-k8s-2.vault-k8s-endpoints.test-autounseal-ful6.svc.cluster.local', port=8200): Max retries exceeded with url: /v1/sys/health (Caused by NewConnectionError('<urllib3.connection.HTTPSConnection object at 0x7fdeaa05d6d0>: Failed to establish a new connection: [Errno 111] Connection refused'))
unit-vault-k8s-1: 21:33:44 ERROR unit.vault-k8s/1.juju-log [vault_client] Error while checking Vault health status: HTTPSConnectionPool(host='vault-k8s-1.vault-k8s-endpoints.test-autounseal-ful6.svc.cluster.local', port=8200): Max retries exceeded with url: /v1/sys/health (Caused by NewConnectionError('<urllib3.connection.HTTPSConnection object at 0x7f73522a4980>: Failed to establish a new connection: [Errno 111] Connection refused'))
unit-vault-k8s-2: 21:33:45 ERROR unit.vault-k8s/2.juju-log vault-peers:1: [vault_client] Error while checking Vault health status: HTTPSConnectionPool(host='vault-k8s-2.vault-k8s-endpoints.test-autounseal-ful6.svc.cluster.local', port=8200): Max retries exceeded with url: /v1/sys/health (Caused by NewConnectionError('<urllib3.connection.HTTPSConnection object at 0x7f6e95982240>: Failed to establish a new connection: [Errno 111] Connection refused'))
unit-vault-k8s-1: 21:33:45 ERROR unit.vault-k8s/1.juju-log [vault_client] Error while checking Vault health status: HTTPSConnectionPool(host='vault-k8s-1.vault-k8s-endpoints.test-autounseal-ful6.svc.cluster.local', port=8200): Max retries exceeded with url: /v1/sys/health (Caused by NewConnectionError('<urllib3.connection.HTTPSConnection object at 0x7ffaba1d4d70>: Failed to establish a new connection: [Errno 111] Connection refused'))
unit-vault-k8s-1: 21:33:47 ERROR unit.vault-k8s/1.juju-log vault-peers:1: [vault_client] Error while checking Vault health status: HTTPSConnectionPool(host='vault-k8s-1.vault-k8s-endpoints.test-autounseal-ful6.svc.cluster.local', port=8200): Max retries exceeded with url: /v1/sys/health (Caused by NewConnectionError('<urllib3.connection.HTTPSConnection object at 0x7f85b3fcfbc0>: Failed to establish a new connection: [Errno 111] Connection refused'))
unit-vault-b-1: 21:37:12 ERROR unit.vault-b/1.juju-log [vault_client] Error while checking Vault health status: HTTPSConnectionPool(host='vault-b-1.vault-b-endpoints.test-autounseal-ful6.svc.cluster.local', port=8200): Max retries exceeded with url: /v1/sys/health (Caused by NewConnectionError('<urllib3.connection.HTTPSConnection object at 0x7fa65d94a150>: Failed to establish a new connection: [Errno 111] Connection refused'))
unit-vault-b-1: 21:37:13 ERROR unit.vault-b/1.juju-log [vault_client] Error while checking Vault health status: HTTPSConnectionPool(host='vault-b-1.vault-b-endpoints.test-autounseal-ful6.svc.cluster.local', port=8200): Max retries exceeded with url: /v1/sys/health (Caused by NewConnectionError('<urllib3.connection.HTTPSConnection object at 0x7f17564d4c80>: Failed to establish a new connection: [Errno 111] Connection refused'))
unit-vault-b-2: 21:37:14 ERROR unit.vault-b/2.juju-log [vault_client] Error while checking Vault health status: HTTPSConnectionPool(host='vault-b-2.vault-b-endpoints.test-autounseal-ful6.svc.cluster.local', port=8200): Max retries exceeded with url: /v1/sys/health (Caused by NewConnectionError('<urllib3.connection.HTTPSConnection object at 0x7f38c2ac2f30>: Failed to establish a new connection: [Errno 111] Connection refused'))
unit-vault-b-1: 21:37:15 ERROR unit.vault-b/1.juju-log vault-autounseal-requires:2: [vault_client] Error while checking Vault health status: HTTPSConnectionPool(host='vault-b-1.vault-b-endpoints.test-autounseal-ful6.svc.cluster.local', port=8200): Max retries exceeded with url: /v1/sys/health (Caused by NewConnectionError('<urllib3.connection.HTTPSConnection object at 0x7fb8c8c2af00>: Failed to establish a new connection: [Errno 111] Connection refused'))
unit-vault-b-2: 21:37:16 ERROR unit.vault-b/2.juju-log [vault_client] Error while checking Vault health status: HTTPSConnectionPool(host='vault-b-2.vault-b-endpoints.test-autounseal-ful6.svc.cluster.local', port=8200): Max retries exceeded with url: /v1/sys/health (Caused by NewConnectionError('<urllib3.connection.HTTPSConnection object at 0x7ff9487e07d0>: Failed to establish a new connection: [Errno 111] Connection refused'))
unit-vault-b-1: 21:37:17 ERROR unit.vault-b/1.juju-log vault-autounseal-requires:2: [vault_client] Error while checking Vault health status: HTTPSConnectionPool(host='vault-b-1.vault-b-endpoints.test-autounseal-ful6.svc.cluster.local', port=8200): Max retries exceeded with url: /v1/sys/health (Caused by NewConnectionError('<urllib3.connection.HTTPSConnection object at 0x7fb2680d5370>: Failed to establish a new connection: [Errno 111] Connection refused'))
unit-vault-b-2: 21:37:18 ERROR unit.vault-b/2.juju-log vault-autounseal-requires:2: [vault_client] Error while checking Vault health status: HTTPSConnectionPool(host='vault-b-2.vault-b-endpoints.test-autounseal-ful6.svc.cluster.local', port=8200): Max retries exceeded with url: /v1/sys/health (Caused by NewConnectionError('<urllib3.connection.HTTPSConnection object at 0x7fa0034db170>: Failed to establish a new connection: [Errno 111] Connection refused'))
unit-vault-b-1: 21:37:20 ERROR unit.vault-b/1.juju-log vault-autounseal-requires:2: [vault_client] Error while checking Vault health status: HTTPSConnectionPool(host='vault-b-1.vault-b-endpoints.test-autounseal-ful6.svc.cluster.local', port=8200): Max retries exceeded with url: /v1/sys/health (Caused by NewConnectionError('<urllib3.connection.HTTPSConnection object at 0x7fd9917deae0>: Failed to establish a new connection: [Errno 111] Connection refused'))
unit-vault-b-2: 21:37:20 ERROR unit.vault-b/2.juju-log vault-autounseal-requires:2: [vault_client] Error while checking Vault health status: HTTPSConnectionPool(host='vault-b-2.vault-b-endpoints.test-autounseal-ful6.svc.cluster.local', port=8200): Max retries exceeded with url: /v1/sys/health (Caused by NewConnectionError('<urllib3.connection.HTTPSConnection object at 0x7faab2235310>: Failed to establish a new connection: [Errno 111] Connection refused'))
unit-vault-b-1: 21:37:22 ERROR unit.vault-b/1.juju-log vault-autounseal-requires:2: [vault_client] Error while checking Vault health status: HTTPSConnectionPool(host='vault-b-1.vault-b-endpoints.test-autounseal-ful6.svc.cluster.local', port=8200): Max retries exceeded with url: /v1/sys/health (Caused by NewConnectionError('<urllib3.connection.HTTPSConnection object at 0x7f7565ad90d0>: Failed to establish a new connection: [Errno 111] Connection refused'))
unit-vault-b-2: 21:37:23 ERROR unit.vault-b/2.juju-log vault-autounseal-requires:2: [vault_client] Error while checking Vault health status: HTTPSConnectionPool(host='vault-b-2.vault-b-endpoints.test-autounseal-ful6.svc.cluster.local', port=8200): Max retries exceeded with url: /v1/sys/health (Caused by NewConnectionError('<urllib3.connection.HTTPSConnection object at 0x7f045622afc0>: Failed to establish a new connection: [Errno 111] Connection refused'))
unit-vault-b-1: 21:37:24 ERROR unit.vault-b/1.juju-log vault-autounseal-requires:2: [vault_client] Error while checking Vault health status: HTTPSConnectionPool(host='vault-b-1.vault-b-endpoints.test-autounseal-ful6.svc.cluster.local', port=8200): Max retries exceeded with url: /v1/sys/health (Caused by NewConnectionError('<urllib3.connection.HTTPSConnection object at 0x7fe6e7ddef00>: Failed to establish a new connection: [Errno 111] Connection refused'))
unit-vault-b-2: 21:37:25 ERROR unit.vault-b/2.juju-log vault-autounseal-requires:2: [vault_client] Error while checking Vault health status: HTTPSConnectionPool(host='vault-b-2.vault-b-endpoints.test-autounseal-ful6.svc.cluster.local', port=8200): Max retries exceeded with url: /v1/sys/health (Caused by NewConnectionError('<urllib3.connection.HTTPSConnection object at 0x7f50c0ce13a0>: Failed to establish a new connection: [Errno 111] Connection refused'))
unit-vault-b-1: 21:37:26 ERROR unit.vault-b/1.juju-log vault-autounseal-requires:2: [vault_client] Error while checking Vault health status: HTTPSConnectionPool(host='vault-b-1.vault-b-endpoints.test-autounseal-ful6.svc.cluster.local', port=8200): Max retries exceeded with url: /v1/sys/health (Caused by NewConnectionError('<urllib3.connection.HTTPSConnection object at 0x7ffbf0c29190>: Failed to establish a new connection: [Errno 111] Connection refused'))
unit-vault-b-2: 21:37:27 ERROR unit.vault-b/2.juju-log vault-autounseal-requires:2: [vault_client] Error while checking Vault health status: HTTPSConnectionPool(host='vault-b-2.vault-b-endpoints.test-autounseal-ful6.svc.cluster.local', port=8200): Max retries exceeded with url: /v1/sys/health (Caused by NewConnectionError('<urllib3.connection.HTTPSConnection object at 0x7fda63add6a0>: Failed to establish a new connection: [Errno 111] Connection refused'))
unit-vault-b-1: 21:37:29 ERROR unit.vault-b/1.juju-log vault-autounseal-requires:2: [vault_client] Error while checking Vault health status: HTTPSConnectionPool(host='vault-b-1.vault-b-endpoints.test-autounseal-ful6.svc.cluster.local', port=8200): Max retries exceeded with url: /v1/sys/health (Caused by NewConnectionError('<urllib3.connection.HTTPSConnection object at 0x7fdc5a5df0e0>: Failed to establish a new connection: [Errno 111] Connection refused'))
unit-vault-b-2: 21:37:29 ERROR unit.vault-b/2.juju-log vault-autounseal-requires:2: [vault_client] Error while checking Vault health status: HTTPSConnectionPool(host='vault-b-2.vault-b-endpoints.test-autounseal-ful6.svc.cluster.local', port=8200): Max retries exceeded with url: /v1/sys/health (Caused by NewConnectionError('<urllib3.connection.HTTPSConnection object at 0x7f8a066e12e0>: Failed to establish a new connection: [Errno 111] Connection refused'))
unit-vault-b-1: 21:37:31 ERROR unit.vault-b/1.juju-log vault-peers:0: [vault_client] Error while checking Vault health status: HTTPSConnectionPool(host='vault-b-1.vault-b-endpoints.test-autounseal-ful6.svc.cluster.local', port=8200): Max retries exceeded with url: /v1/sys/health (Caused by NewConnectionError('<urllib3.connection.HTTPSConnection object at 0x7f0b83dd4500>: Failed to establish a new connection: [Errno 111] Connection refused'))
unit-vault-b-2: 21:37:31 ERROR unit.vault-b/2.juju-log vault-autounseal-requires:2: [vault_client] Error while checking Vault health status: HTTPSConnectionPool(host='vault-b-2.vault-b-endpoints.test-autounseal-ful6.svc.cluster.local', port=8200): Max retries exceeded with url: /v1/sys/health (Caused by NewConnectionError('<urllib3.connection.HTTPSConnection object at 0x7f76120daae0>: Failed to establish a new connection: [Errno 111] Connection refused'))
unit-vault-b-2: 21:37:33 ERROR unit.vault-b/2.juju-log vault-peers:0: [vault_client] Error while checking Vault health status: HTTPSConnectionPool(host='vault-b-2.vault-b-endpoints.test-autounseal-ful6.svc.cluster.local', port=8200): Max retries exceeded with url: /v1/sys/health (Caused by NewConnectionError('<urllib3.connection.HTTPSConnection object at 0x7f146c224ec0>: Failed to establish a new connection: [Errno 111] Connection refused'))
unit-vault-b-0: 21:38:23 ERROR unit.vault-b/0.juju-log [vault_client] Error while checking Vault health status: HTTPSConnectionPool(host='vault-b-0.vault-b-endpoints.test-autounseal-ful6.svc.cluster.local', port=8200): Max retries exceeded with url: /v1/sys/health (Caused by NewConnectionError('<urllib3.connection.HTTPSConnection object at 0x7f6688835e80>: Failed to establish a new connection: [Errno 111] Connection refused'))
unit-vault-b-1: 21:38:52 ERROR unit.vault-b/1.juju-log [vault_client] Error while checking Vault health status: HTTPSConnectionPool(host='vault-b-1.vault-b-endpoints.test-autounseal-ful6.svc.cluster.local', port=8200): Max retries exceeded with url: /v1/sys/health (Caused by NewConnectionError('<urllib3.connection.HTTPSConnection object at 0x7f6c7af9ee10>: Failed to establish a new connection: [Errno 111] Connection refused'))
unit-vault-b-2: 21:38:52 ERROR unit.vault-b/2.juju-log [vault_client] Error while checking Vault health status: HTTPSConnectionPool(host='vault-b-2.vault-b-endpoints.test-autounseal-ful6.svc.cluster.local', port=8200): Max retries exceeded with url: /v1/sys/health (Caused by NewConnectionError('<urllib3.connection.HTTPSConnection object at 0x7f7787090200>: Failed to establish a new connection: [Errno 111] Connection refused'))
unit-vault-b-0: 21:38:52 ERROR unit.vault-b/0.juju-log [vault_client] Error while checking Vault health status: HTTPSConnectionPool(host='vault-b-0.vault-b-endpoints.test-autounseal-ful6.svc.cluster.local', port=8200): Max retries exceeded with url: /v1/sys/health (Caused by NewConnectionError('<urllib3.connection.HTTPSConnection object at 0x7fb77ced33b0>: Failed to establish a new connection: [Errno 111] Connection refused'))
model-3fe01563-76f1-46f0-8cea-9c619dd7935d: 21:38:58 ERROR juju.worker.dependency "log-sender" manifold worker returned unexpected error: sending log message: websocket: close 1005 (no status): websocket: close sent
unit-vault-k8s-0: 21:39:03 ERROR juju.worker.dependency "log-sender" manifold worker returned unexpected error: sending log message: websocket: close 1005 (no status): websocket: close sent
unit-vault-b-1: 21:39:03 ERROR juju.worker.dependency "log-sender" manifold worker returned unexpected error: sending log message: websocket: close 1005 (no status): websocket: close sent
unit-vault-b-2: 21:39:03 ERROR juju.worker.dependency "log-sender" manifold worker returned unexpected error: sending log message: websocket: close 1005 (no status): websocket: close sent
unit-vault-k8s-2: 21:39:05 ERROR juju.worker.dependency "log-sender" manifold worker returned unexpected error: sending log message: write tcp 10.1.7.28:39170->10.152.183.132:17070: write: connection reset by peer: write tcp 10.1.7.28:39170->10.152.183.132:17070: write: connection reset by peer
unit-vault-k8s-1: 21:39:08 ERROR juju.worker.dependency "log-sender" manifold worker returned unexpected error: sending log message: websocket: close 1005 (no status): websocket: close sent
unit-vault-b-0: 21:39:10 ERROR juju.worker.dependency "log-sender" manifold worker returned unexpected error: sending log message: websocket: close 1005 (no status): websocket: close sent

[32mINFO    [0m pytest_operator.plugin:plugin.py:1063 Resetting model test-autounseal-ful6...
[32mINFO    [0m pytest_operator.plugin:plugin.py:1052    Destroying applications vault-b
[32mINFO    [0m pytest_operator.plugin:plugin.py:1052    Destroying applications vault-k8s
[32mINFO    [0m pytest_operator.plugin:plugin.py:1068 Not waiting on reset to complete.
[32mINFO    [0m pytest_operator.plugin:plugin.py:1039 Forgetting model main...