[32mINFO    [0m pytest_operator.plugin:plugin.py:929 Model status:

Model                  Controller                Cloud/Region        Version  SLA          Timestamp
test-integration-32gt  github-pr-a6ae0-microk8s  microk8s/localhost  3.6.2    unsupported  18:28:51Z

App        Version  Status   Scale  Charm      Channel  Rev  Address         Exposed  Message
vault-b             waiting    1/0  vault-k8s             1  10.152.183.107  no       Waiting for vault to be available
vault-k8s           active       3  vault-k8s             0  10.152.183.230  no       

Unit          Workload  Agent      Address     Ports  Message
vault-b/0*    waiting   executing  10.1.53.53         Waiting for vault to be available
vault-k8s/0   active    executing  10.1.53.16         
vault-k8s/1*  active    idle       10.1.53.25         
vault-k8s/2   active    executing  10.1.53.23         

[32mINFO    [0m pytest_operator.plugin:plugin.py:935 Juju error logs:

unit-vault-k8s-1: 17:47:03 ERROR unit.vault-k8s/1.juju-log [vault_client] Error while checking Vault health status: HTTPSConnectionPool(host='vault-k8s-1.vault-k8s-endpoints.test-integration-32gt.svc.cluster.local', port=8200): Max retries exceeded with url: /v1/sys/health (Caused by NewConnectionError('<urllib3.connection.HTTPSConnection object at 0x7337c4d51030>: Failed to establish a new connection: [Errno 111] Connection refused'))
unit-vault-k8s-3: 17:48:29 ERROR unit.vault-k8s/3.juju-log vault-peers:0: Raft cluster is not healthy. {'failure_tolerance': 1, 'healthy': False, 'leader': 'test-integration-32gt-vault-k8s/0', 'servers': {'test-integration-32gt-vault-k8s/0': {'id': 'test-integration-32gt-vault-k8s/0', 'name': 'test-integration-32gt-vault-k8s/0', 'address': 'vault-k8s-0.vault-k8s-endpoints.test-integration-32gt.svc.cluster.local:8201', 'node_status': 'alive', 'last_contact': '0s', 'last_term': 4, 'last_index': 166, 'healthy': True, 'stable_since': '2025-02-05T17:46:33.00817908Z', 'status': 'leader', 'version': '1.16.3', 'node_type': 'voter'}, 'test-integration-32gt-vault-k8s/1': {'id': 'test-integration-32gt-vault-k8s/1', 'name': 'test-integration-32gt-vault-k8s/1', 'address': 'vault-k8s-1.vault-k8s-endpoints.test-integration-32gt.svc.cluster.local:8201', 'node_status': 'alive', 'last_contact': '2.81617149s', 'last_term': 4, 'last_index': 164, 'healthy': True, 'stable_since': '2025-02-05T17:46:33.00817908Z', 'status': 'voter', 'version': '1.16.3', 'node_type': 'voter'}, 'test-integration-32gt-vault-k8s/2': {'id': 'test-integration-32gt-vault-k8s/2', 'name': 'test-integration-32gt-vault-k8s/2', 'address': 'vault-k8s-2.vault-k8s-endpoints.test-integration-32gt.svc.cluster.local:8201', 'node_status': 'alive', 'last_contact': '3.998140928s', 'last_term': 4, 'last_index': 164, 'healthy': True, 'stable_since': '2025-02-05T17:46:33.00817908Z', 'status': 'voter', 'version': '1.16.3', 'node_type': 'voter'}, 'test-integration-32gt-vault-k8s/3': {'id': 'test-integration-32gt-vault-k8s/3', 'name': 'test-integration-32gt-vault-k8s/3', 'address': 'vault-k8s-3.vault-k8s-endpoints.test-integration-32gt.svc.cluster.local:8201', 'node_status': 'alive', 'last_contact': '975.640443ms', 'last_term': 0, 'last_index': 0, 'healthy': False, 'stable_since': '2025-02-05T17:48:29.008503258Z', 'status': 'non-voter', 'version': '1.16.3', 'node_type': 'voter'}}, 'voters': ['test-integration-32gt-vault-k8s/0', 'test-integration-32gt-vault-k8s/1', 'test-integration-32gt-vault-k8s/2']}
unit-loki-k8s-0: 18:04:19 ERROR unit.loki-k8s/0.juju-log Uncaught exception while in charm code:
Traceback (most recent call last):
  File "./src/charm.py", line 917, in <module>
    main(LokiOperatorCharm)
  File "/var/lib/juju/agents/unit-loki-k8s-0/charm/venv/ops/main.py", line 45, in main
    return _main.main(charm_class=charm_class, use_juju_for_storage=use_juju_for_storage)
  File "/var/lib/juju/agents/unit-loki-k8s-0/charm/venv/ops/_main.py", line 543, in main
    manager.run()
  File "/var/lib/juju/agents/unit-loki-k8s-0/charm/venv/ops/_main.py", line 529, in run
    self._emit()
  File "/var/lib/juju/agents/unit-loki-k8s-0/charm/venv/ops/_main.py", line 518, in _emit
    _emit_charm_event(self.charm, self.dispatcher.event_name, self._juju_context)
  File "/var/lib/juju/agents/unit-loki-k8s-0/charm/venv/ops/_main.py", line 134, in _emit_charm_event
    event_to_emit.emit(*args, **kwargs)
  File "/var/lib/juju/agents/unit-loki-k8s-0/charm/venv/ops/framework.py", line 347, in emit
    framework._emit(event)
  File "/var/lib/juju/agents/unit-loki-k8s-0/charm/venv/ops/framework.py", line 857, in _emit
    self._reemit(event_path)
  File "/var/lib/juju/agents/unit-loki-k8s-0/charm/venv/ops/framework.py", line 947, in _reemit
    custom_handler(event)
  File "/var/lib/juju/agents/unit-loki-k8s-0/charm/lib/charms/tempo_coordinator_k8s/v0/charm_tracing.py", line 1064, in wrapped_function
    return callable(*args, **kwargs)  # type: ignore
  File "./src/charm.py", line 322, in _on_node_exporter_pebble_ready
    self._node_exporter_container.add_layer("node-exporter", new_layer, combine=True)
  File "/var/lib/juju/agents/unit-loki-k8s-0/charm/venv/ops/model.py", line 2439, in add_layer
    self._pebble.add_layer(label, layer, combine=combine)
  File "/var/lib/juju/agents/unit-loki-k8s-0/charm/venv/ops/pebble.py", line 2367, in add_layer
    self._request('POST', '/v1/layers', body=body)
  File "/var/lib/juju/agents/unit-loki-k8s-0/charm/venv/ops/pebble.py", line 2010, in _request
    response = self._request_raw(method, path, query, headers, data)
  File "/var/lib/juju/agents/unit-loki-k8s-0/charm/venv/ops/pebble.py", line 2063, in _request_raw
    raise ConnectionError(
ops.pebble.ConnectionError: Could not connect to Pebble: socket not found at '/charm/containers/node-exporter/pebble.socket' (container restarted?)
unit-loki-k8s-0: 18:04:19 ERROR juju.worker.uniter.operation hook "node-exporter-pebble-ready" (via hook dispatching script: dispatch) failed: exit status 1
unit-loki-k8s-0: 18:04:19 ERROR juju.worker.uniter pebble poll failed for container "node-exporter": failed to send pebble-ready event: hook failed
unit-prometheus-k8s-0: 18:05:30 ERROR unit.prometheus-k8s/0.juju-log Failed to apply resource limit patch: Unauthorized
unit-prometheus-k8s-0: 18:10:36 ERROR unit.prometheus-k8s/0.juju-log Failed to apply resource limit patch: Unauthorized
unit-prometheus-k8s-0: 18:13:06 ERROR juju.worker.uniter pebble poll failed for container "prometheus": failed to send pebble-ready event: terminated
controller-0: 18:17:53 ERROR juju.worker.caasunitprovisioner stopping application worker for minio: Operation cannot be fulfilled on statefulsets.apps "minio": StorageError: invalid object, Code: 4, Key: /registry/statefulsets/test-integration-32gt/minio, ResourceVersion: 0, AdditionalErrorMsg: Precondition failed: UID in precondition: 91bcfb45-24b0-4e39-9d0e-4de7fe3835e7, UID in object meta: 
unit-vault-b-0: 18:18:56 ERROR unit.vault-b/0.juju-log vault-autounseal-requires:13: [vault_client] Error while checking Vault health status: HTTPSConnectionPool(host='vault-b-0.vault-b-endpoints.test-integration-32gt.svc.cluster.local', port=8200): Max retries exceeded with url: /v1/sys/health (Caused by NewConnectionError('<urllib3.connection.HTTPSConnection object at 0x7722da0e9d80>: Failed to establish a new connection: [Errno 111] Connection refused'))
unit-vault-b-0: 18:18:56 ERROR unit.vault-b/0.juju-log vault-autounseal-requires:13: [vault_client] Error while checking Vault health status: HTTPSConnectionPool(host='vault-b-0.vault-b-endpoints.test-integration-32gt.svc.cluster.local', port=8200): Max retries exceeded with url: /v1/sys/health (Caused by NewConnectionError('<urllib3.connection.HTTPSConnection object at 0x7722d9f389a0>: Failed to establish a new connection: [Errno 111] Connection refused'))
unit-vault-b-0: 18:18:58 ERROR unit.vault-b/0.juju-log vault-autounseal-requires:13: [vault_client] Error while checking Vault health status: HTTPSConnectionPool(host='vault-b-0.vault-b-endpoints.test-integration-32gt.svc.cluster.local', port=8200): Max retries exceeded with url: /v1/sys/health (Caused by NewConnectionError('<urllib3.connection.HTTPSConnection object at 0x7c02937c7dc0>: Failed to establish a new connection: [Errno 111] Connection refused'))
unit-vault-b-0: 18:18:58 ERROR unit.vault-b/0.juju-log vault-autounseal-requires:13: [vault_client] Error while checking Vault health status: HTTPSConnectionPool(host='vault-b-0.vault-b-endpoints.test-integration-32gt.svc.cluster.local', port=8200): Max retries exceeded with url: /v1/sys/health (Caused by NewConnectionError('<urllib3.connection.HTTPSConnection object at 0x7c02937e23b0>: Failed to establish a new connection: [Errno 111] Connection refused'))
unit-vault-b-0: 18:18:59 ERROR unit.vault-b/0.juju-log vault-autounseal-requires:13: [vault_client] Error while checking Vault health status: HTTPSConnectionPool(host='vault-b-0.vault-b-endpoints.test-integration-32gt.svc.cluster.local', port=8200): Max retries exceeded with url: /v1/sys/health (Caused by NewConnectionError('<urllib3.connection.HTTPSConnection object at 0x706555231360>: Failed to establish a new connection: [Errno 111] Connection refused'))
unit-vault-b-0: 18:19:01 ERROR unit.vault-b/0.juju-log vault-autounseal-requires:13: [vault_client] Error while checking Vault health status: HTTPSConnectionPool(host='vault-b-0.vault-b-endpoints.test-integration-32gt.svc.cluster.local', port=8200): Max retries exceeded with url: /v1/sys/health (Caused by NewConnectionError('<urllib3.connection.HTTPSConnection object at 0x7002e0ddbe50>: Failed to establish a new connection: [Errno 111] Connection refused'))
unit-vault-b-0: 18:19:01 ERROR unit.vault-b/0.juju-log vault-autounseal-requires:13: [vault_client] Error while checking Vault health status: HTTPSConnectionPool(host='vault-b-0.vault-b-endpoints.test-integration-32gt.svc.cluster.local', port=8200): Max retries exceeded with url: /v1/sys/health (Caused by NewConnectionError('<urllib3.connection.HTTPSConnection object at 0x7002e0dde440>: Failed to establish a new connection: [Errno 111] Connection refused'))
unit-vault-b-0: 18:19:02 ERROR unit.vault-b/0.juju-log vault-autounseal-requires:13: [vault_client] Error while checking Vault health status: HTTPSConnectionPool(host='vault-b-0.vault-b-endpoints.test-integration-32gt.svc.cluster.local', port=8200): Max retries exceeded with url: /v1/sys/health (Caused by NewConnectionError('<urllib3.connection.HTTPSConnection object at 0x72eb0fad5360>: Failed to establish a new connection: [Errno 111] Connection refused'))
unit-vault-b-0: 18:19:04 ERROR unit.vault-b/0.juju-log vault-autounseal-requires:13: [vault_client] Error while checking Vault health status: HTTPSConnectionPool(host='vault-b-0.vault-b-endpoints.test-integration-32gt.svc.cluster.local', port=8200): Max retries exceeded with url: /v1/sys/health (Caused by NewConnectionError('<urllib3.connection.HTTPSConnection object at 0x7305375bbee0>: Failed to establish a new connection: [Errno 111] Connection refused'))
unit-vault-b-0: 18:19:04 ERROR unit.vault-b/0.juju-log vault-autounseal-requires:13: [vault_client] Error while checking Vault health status: HTTPSConnectionPool(host='vault-b-0.vault-b-endpoints.test-integration-32gt.svc.cluster.local', port=8200): Max retries exceeded with url: /v1/sys/health (Caused by NewConnectionError('<urllib3.connection.HTTPSConnection object at 0x7305375b24d0>: Failed to establish a new connection: [Errno 111] Connection refused'))
unit-vault-b-0: 18:20:01 ERROR unit.vault-b/0.juju-log [vault_client] Error while checking Vault health status: HTTPSConnectionPool(host='vault-b-0.vault-b-endpoints.test-integration-32gt.svc.cluster.local', port=8200): Max retries exceeded with url: /v1/sys/health (Caused by NewConnectionError('<urllib3.connection.HTTPSConnection object at 0x7518a65a0190>: Failed to establish a new connection: [Errno 111] Connection refused'))
unit-vault-b-0: 18:20:01 ERROR unit.vault-b/0.juju-log [vault_client] Error while checking Vault health status: HTTPSConnectionPool(host='vault-b-0.vault-b-endpoints.test-integration-32gt.svc.cluster.local', port=8200): Max retries exceeded with url: /v1/sys/health (Caused by NewConnectionError('<urllib3.connection.HTTPSConnection object at 0x7518a7011c90>: Failed to establish a new connection: [Errno 111] Connection refused'))
unit-vault-b-0: 18:20:02 ERROR unit.vault-b/0.juju-log [vault_client] Error while checking Vault health status: HTTPSConnectionPool(host='vault-b-0.vault-b-endpoints.test-integration-32gt.svc.cluster.local', port=8200): Max retries exceeded with url: /v1/sys/health (Caused by NewConnectionError('<urllib3.connection.HTTPSConnection object at 0x7fb23f6e0fa0>: Failed to establish a new connection: [Errno 111] Connection refused'))
unit-vault-b-0: 18:21:05 ERROR unit.vault-b/0.juju-log [vault_client] Error while checking Vault health status: HTTPSConnectionPool(host='vault-b-0.vault-b-endpoints.test-integration-32gt.svc.cluster.local', port=8200): Max retries exceeded with url: /v1/sys/health (Caused by NewConnectionError('<urllib3.connection.HTTPSConnection object at 0x74a807494130>: Failed to establish a new connection: [Errno 111] Connection refused'))
unit-vault-b-0: 18:21:05 ERROR unit.vault-b/0.juju-log [vault_client] Error while checking Vault health status: HTTPSConnectionPool(host='vault-b-0.vault-b-endpoints.test-integration-32gt.svc.cluster.local', port=8200): Max retries exceeded with url: /v1/sys/health (Caused by NewConnectionError('<urllib3.connection.HTTPSConnection object at 0x74a807f11cf0>: Failed to establish a new connection: [Errno 111] Connection refused'))
unit-vault-b-0: 18:21:07 ERROR unit.vault-b/0.juju-log [vault_client] Error while checking Vault health status: HTTPSConnectionPool(host='vault-b-0.vault-b-endpoints.test-integration-32gt.svc.cluster.local', port=8200): Max retries exceeded with url: /v1/sys/health (Caused by NewConnectionError('<urllib3.connection.HTTPSConnection object at 0x78968eb08fd0>: Failed to establish a new connection: [Errno 111] Connection refused'))
unit-vault-b-0: 18:21:08 ERROR unit.vault-b/0.juju-log [vault_client] Error while checking Vault health status: HTTPSConnectionPool(host='vault-b-0.vault-b-endpoints.test-integration-32gt.svc.cluster.local', port=8200): Max retries exceeded with url: /v1/sys/health (Caused by NewConnectionError('<urllib3.connection.HTTPSConnection object at 0x72ca2464cfd0>: Failed to establish a new connection: [Errno 111] Connection refused'))
unit-vault-b-0: 18:22:10 ERROR unit.vault-b/0.juju-log [vault_client] Error while checking Vault health status: HTTPSConnectionPool(host='vault-b-0.vault-b-endpoints.test-integration-32gt.svc.cluster.local', port=8200): Max retries exceeded with url: /v1/sys/health (Caused by NewConnectionError('<urllib3.connection.HTTPSConnection object at 0x7f8ae289c130>: Failed to establish a new connection: [Errno 111] Connection refused'))
unit-vault-b-0: 18:22:10 ERROR unit.vault-b/0.juju-log [vault_client] Error while checking Vault health status: HTTPSConnectionPool(host='vault-b-0.vault-b-endpoints.test-integration-32gt.svc.cluster.local', port=8200): Max retries exceeded with url: /v1/sys/health (Caused by NewConnectionError('<urllib3.connection.HTTPSConnection object at 0x7f8ae3311c30>: Failed to establish a new connection: [Errno 111] Connection refused'))
unit-vault-b-0: 18:22:12 ERROR unit.vault-b/0.juju-log [vault_client] Error while checking Vault health status: HTTPSConnectionPool(host='vault-b-0.vault-b-endpoints.test-integration-32gt.svc.cluster.local', port=8200): Max retries exceeded with url: /v1/sys/health (Caused by NewConnectionError('<urllib3.connection.HTTPSConnection object at 0x707cf8238f40>: Failed to establish a new connection: [Errno 111] Connection refused'))
unit-vault-b-0: 18:22:13 ERROR unit.vault-b/0.juju-log [vault_client] Error while checking Vault health status: HTTPSConnectionPool(host='vault-b-0.vault-b-endpoints.test-integration-32gt.svc.cluster.local', port=8200): Max retries exceeded with url: /v1/sys/health (Caused by NewConnectionError('<urllib3.connection.HTTPSConnection object at 0x708799b00fd0>: Failed to establish a new connection: [Errno 111] Connection refused'))
unit-vault-b-0: 18:23:11 ERROR unit.vault-b/0.juju-log [vault_client] Error while checking Vault health status: HTTPSConnectionPool(host='vault-b-0.vault-b-endpoints.test-integration-32gt.svc.cluster.local', port=8200): Max retries exceeded with url: /v1/sys/health (Caused by NewConnectionError('<urllib3.connection.HTTPSConnection object at 0x731769914190>: Failed to establish a new connection: [Errno 111] Connection refused'))
unit-vault-b-0: 18:23:12 ERROR unit.vault-b/0.juju-log [vault_client] Error while checking Vault health status: HTTPSConnectionPool(host='vault-b-0.vault-b-endpoints.test-integration-32gt.svc.cluster.local', port=8200): Max retries exceeded with url: /v1/sys/health (Caused by NewConnectionError('<urllib3.connection.HTTPSConnection object at 0x731769a1dc60>: Failed to establish a new connection: [Errno 111] Connection refused'))
unit-vault-b-0: 18:23:13 ERROR unit.vault-b/0.juju-log [vault_client] Error while checking Vault health status: HTTPSConnectionPool(host='vault-b-0.vault-b-endpoints.test-integration-32gt.svc.cluster.local', port=8200): Max retries exceeded with url: /v1/sys/health (Caused by NewConnectionError('<urllib3.connection.HTTPSConnection object at 0x7ad589115000>: Failed to establish a new connection: [Errno 111] Connection refused'))
unit-vault-b-0: 18:23:14 ERROR unit.vault-b/0.juju-log [vault_client] Error while checking Vault health status: HTTPSConnectionPool(host='vault-b-0.vault-b-endpoints.test-integration-32gt.svc.cluster.local', port=8200): Max retries exceeded with url: /v1/sys/health (Caused by NewConnectionError('<urllib3.connection.HTTPSConnection object at 0x7255af439030>: Failed to establish a new connection: [Errno 111] Connection refused'))
unit-vault-b-0: 18:24:14 ERROR unit.vault-b/0.juju-log [vault_client] Error while checking Vault health status: HTTPSConnectionPool(host='vault-b-0.vault-b-endpoints.test-integration-32gt.svc.cluster.local', port=8200): Max retries exceeded with url: /v1/sys/health (Caused by NewConnectionError('<urllib3.connection.HTTPSConnection object at 0x770473390190>: Failed to establish a new connection: [Errno 111] Connection refused'))
unit-vault-b-0: 18:24:14 ERROR unit.vault-b/0.juju-log [vault_client] Error while checking Vault health status: HTTPSConnectionPool(host='vault-b-0.vault-b-endpoints.test-integration-32gt.svc.cluster.local', port=8200): Max retries exceeded with url: /v1/sys/health (Caused by NewConnectionError('<urllib3.connection.HTTPSConnection object at 0x770473e09c60>: Failed to establish a new connection: [Errno 111] Connection refused'))
unit-vault-b-0: 18:24:15 ERROR unit.vault-b/0.juju-log [vault_client] Error while checking Vault health status: HTTPSConnectionPool(host='vault-b-0.vault-b-endpoints.test-integration-32gt.svc.cluster.local', port=8200): Max retries exceeded with url: /v1/sys/health (Caused by NewConnectionError('<urllib3.connection.HTTPSConnection object at 0x7414b6cd4fd0>: Failed to establish a new connection: [Errno 111] Connection refused'))
unit-vault-b-0: 18:24:16 ERROR unit.vault-b/0.juju-log [vault_client] Error while checking Vault health status: HTTPSConnectionPool(host='vault-b-0.vault-b-endpoints.test-integration-32gt.svc.cluster.local', port=8200): Max retries exceeded with url: /v1/sys/health (Caused by NewConnectionError('<urllib3.connection.HTTPSConnection object at 0x7359c0d08fd0>: Failed to establish a new connection: [Errno 111] Connection refused'))
unit-vault-b-0: 18:25:15 ERROR unit.vault-b/0.juju-log [vault_client] Error while checking Vault health status: HTTPSConnectionPool(host='vault-b-0.vault-b-endpoints.test-integration-32gt.svc.cluster.local', port=8200): Max retries exceeded with url: /v1/sys/health (Caused by NewConnectionError('<urllib3.connection.HTTPSConnection object at 0x71f4b2bb0190>: Failed to establish a new connection: [Errno 111] Connection refused'))
unit-vault-b-0: 18:25:15 ERROR unit.vault-b/0.juju-log [vault_client] Error while checking Vault health status: HTTPSConnectionPool(host='vault-b-0.vault-b-endpoints.test-integration-32gt.svc.cluster.local', port=8200): Max retries exceeded with url: /v1/sys/health (Caused by NewConnectionError('<urllib3.connection.HTTPSConnection object at 0x71f4b3521c60>: Failed to establish a new connection: [Errno 111] Connection refused'))
unit-vault-b-0: 18:25:17 ERROR unit.vault-b/0.juju-log [vault_client] Error while checking Vault health status: HTTPSConnectionPool(host='vault-b-0.vault-b-endpoints.test-integration-32gt.svc.cluster.local', port=8200): Max retries exceeded with url: /v1/sys/health (Caused by NewConnectionError('<urllib3.connection.HTTPSConnection object at 0x795bf8f18fa0>: Failed to establish a new connection: [Errno 111] Connection refused'))
unit-vault-b-0: 18:25:18 ERROR unit.vault-b/0.juju-log [vault_client] Error while checking Vault health status: HTTPSConnectionPool(host='vault-b-0.vault-b-endpoints.test-integration-32gt.svc.cluster.local', port=8200): Max retries exceeded with url: /v1/sys/health (Caused by NewConnectionError('<urllib3.connection.HTTPSConnection object at 0x7a5652f09000>: Failed to establish a new connection: [Errno 111] Connection refused'))
unit-vault-b-0: 18:26:09 ERROR unit.vault-b/0.juju-log [vault_client] Error while checking Vault health status: HTTPSConnectionPool(host='vault-b-0.vault-b-endpoints.test-integration-32gt.svc.cluster.local', port=8200): Max retries exceeded with url: /v1/sys/health (Caused by NewConnectionError('<urllib3.connection.HTTPSConnection object at 0x75742b5d0130>: Failed to establish a new connection: [Errno 111] Connection refused'))
unit-vault-b-0: 18:26:09 ERROR unit.vault-b/0.juju-log [vault_client] Error while checking Vault health status: HTTPSConnectionPool(host='vault-b-0.vault-b-endpoints.test-integration-32gt.svc.cluster.local', port=8200): Max retries exceeded with url: /v1/sys/health (Caused by NewConnectionError('<urllib3.connection.HTTPSConnection object at 0x75742bf21c90>: Failed to establish a new connection: [Errno 111] Connection refused'))
unit-vault-b-0: 18:26:11 ERROR unit.vault-b/0.juju-log [vault_client] Error while checking Vault health status: HTTPSConnectionPool(host='vault-b-0.vault-b-endpoints.test-integration-32gt.svc.cluster.local', port=8200): Max retries exceeded with url: /v1/sys/health (Caused by NewConnectionError('<urllib3.connection.HTTPSConnection object at 0x79e1056d5030>: Failed to establish a new connection: [Errno 111] Connection refused'))
unit-vault-b-0: 18:26:12 ERROR unit.vault-b/0.juju-log [vault_client] Error while checking Vault health status: HTTPSConnectionPool(host='vault-b-0.vault-b-endpoints.test-integration-32gt.svc.cluster.local', port=8200): Max retries exceeded with url: /v1/sys/health (Caused by NewConnectionError('<urllib3.connection.HTTPSConnection object at 0x7875616e0fd0>: Failed to establish a new connection: [Errno 111] Connection refused'))
unit-vault-b-0: 18:27:11 ERROR unit.vault-b/0.juju-log [vault_client] Error while checking Vault health status: HTTPSConnectionPool(host='vault-b-0.vault-b-endpoints.test-integration-32gt.svc.cluster.local', port=8200): Max retries exceeded with url: /v1/sys/health (Caused by NewConnectionError('<urllib3.connection.HTTPSConnection object at 0x7d0a2b5a4190>: Failed to establish a new connection: [Errno 111] Connection refused'))
unit-vault-b-0: 18:27:11 ERROR unit.vault-b/0.juju-log [vault_client] Error while checking Vault health status: HTTPSConnectionPool(host='vault-b-0.vault-b-endpoints.test-integration-32gt.svc.cluster.local', port=8200): Max retries exceeded with url: /v1/sys/health (Caused by NewConnectionError('<urllib3.connection.HTTPSConnection object at 0x7d0a2b69dcc0>: Failed to establish a new connection: [Errno 111] Connection refused'))
unit-vault-b-0: 18:27:12 ERROR unit.vault-b/0.juju-log [vault_client] Error while checking Vault health status: HTTPSConnectionPool(host='vault-b-0.vault-b-endpoints.test-integration-32gt.svc.cluster.local', port=8200): Max retries exceeded with url: /v1/sys/health (Caused by NewConnectionError('<urllib3.connection.HTTPSConnection object at 0x7b2883b14fa0>: Failed to establish a new connection: [Errno 111] Connection refused'))
unit-vault-b-0: 18:27:13 ERROR unit.vault-b/0.juju-log [vault_client] Error while checking Vault health status: HTTPSConnectionPool(host='vault-b-0.vault-b-endpoints.test-integration-32gt.svc.cluster.local', port=8200): Max retries exceeded with url: /v1/sys/health (Caused by NewConnectionError('<urllib3.connection.HTTPSConnection object at 0x7fc4f9514fd0>: Failed to establish a new connection: [Errno 111] Connection refused'))
unit-vault-b-0: 18:28:16 ERROR unit.vault-b/0.juju-log [vault_client] Error while checking Vault health status: HTTPSConnectionPool(host='vault-b-0.vault-b-endpoints.test-integration-32gt.svc.cluster.local', port=8200): Max retries exceeded with url: /v1/sys/health (Caused by NewConnectionError('<urllib3.connection.HTTPSConnection object at 0x70049cd68190>: Failed to establish a new connection: [Errno 111] Connection refused'))
unit-vault-b-0: 18:28:16 ERROR unit.vault-b/0.juju-log [vault_client] Error while checking Vault health status: HTTPSConnectionPool(host='vault-b-0.vault-b-endpoints.test-integration-32gt.svc.cluster.local', port=8200): Max retries exceeded with url: /v1/sys/health (Caused by NewConnectionError('<urllib3.connection.HTTPSConnection object at 0x70049d8a5cc0>: Failed to establish a new connection: [Errno 111] Connection refused'))
unit-vault-b-0: 18:28:17 ERROR unit.vault-b/0.juju-log [vault_client] Error while checking Vault health status: HTTPSConnectionPool(host='vault-b-0.vault-b-endpoints.test-integration-32gt.svc.cluster.local', port=8200): Max retries exceeded with url: /v1/sys/health (Caused by NewConnectionError('<urllib3.connection.HTTPSConnection object at 0x708fd7accfa0>: Failed to establish a new connection: [Errno 111] Connection refused'))
unit-vault-b-0: 18:28:19 ERROR unit.vault-b/0.juju-log [vault_client] Error while checking Vault health status: HTTPSConnectionPool(host='vault-b-0.vault-b-endpoints.test-integration-32gt.svc.cluster.local', port=8200): Max retries exceeded with url: /v1/sys/health (Caused by NewConnectionError('<urllib3.connection.HTTPSConnection object at 0x77dc98300fa0>: Failed to establish a new connection: [Errno 111] Connection refused'))

[32mINFO    [0m pytest_operator.plugin:plugin.py:949 juju-crashdump finished [0]
[32mINFO    [0m pytest_operator.plugin:plugin.py:1041 Resetting model test-integration-32gt...
[32mINFO    [0m pytest_operator.plugin:plugin.py:1030    Destroying applications vault-k8s
[32mINFO    [0m pytest_operator.plugin:plugin.py:1030    Destroying applications vault-b
[32mINFO    [0m pytest_operator.plugin:plugin.py:1046 Not waiting on reset to complete.
[32mINFO    [0m pytest_operator.plugin:plugin.py:1017 Forgetting model main...