[32mINFO    [0m juju.model:__init__.py:3254 Waiting for model:
  vault-k8s/0 [executing] active: 
  vault-k8s/1 [executing] active: 
  vault-k8s/2 [executing] active: 
[32mINFO    [0m juju.model:__init__.py:3254 Waiting for model:
  tls-certificates-requirer/0 [executing] active: Certificate relation is created
[32mINFO    [0m pytest_operator.plugin:plugin.py:937 Model status:

Model          Controller                Cloud/Region        Version  SLA          Timestamp
test-pki-jqcf  github-pr-4f7d0-microk8s  microk8s/localhost  3.6.8    unsupported  12:48:58Z

App                        Version  Status  Scale  Charm                      Channel        Rev  Address         Exposed  Message
self-signed-certificates            active      1  self-signed-certificates   1/stable       317  10.152.183.81   no       
tls-certificates-requirer           active      1  tls-certificates-requirer  latest/stable   93  10.152.183.93   no       Unit certificate is available
vault-k8s                           active      3  vault-k8s                                   0  10.152.183.109  no       

Unit                          Workload  Agent  Address       Ports  Message
self-signed-certificates/0*   active    idle   10.1.169.148         
tls-certificates-requirer/0*  active    idle   10.1.169.152         Unit certificate is available
vault-k8s/0*                  active    idle   10.1.169.144         
vault-k8s/1                   active    idle   10.1.169.154         
vault-k8s/2                   active    idle   10.1.169.153         

[32mINFO    [0m pytest_operator.plugin:plugin.py:943 Juju error logs:

unit-vault-k8s-2: 12:47:06 ERROR unit.vault-k8s/2.juju-log [vault_client] Error while checking Vault health status: HTTPSConnectionPool(host='vault-k8s-2.vault-k8s-endpoints.test-pki-jqcf.svc.cluster.local', port=8200): Max retries exceeded with url: /v1/sys/health (Caused by NewConnectionError('<urllib3.connection.HTTPSConnection object at 0x7f0a113575f0>: Failed to establish a new connection: [Errno 111] Connection refused'))
unit-vault-k8s-1: 12:47:07 ERROR unit.vault-k8s/1.juju-log [vault_client] Error while checking Vault health status: HTTPSConnectionPool(host='vault-k8s-1.vault-k8s-endpoints.test-pki-jqcf.svc.cluster.local', port=8200): Max retries exceeded with url: /v1/sys/health (Caused by NewConnectionError('<urllib3.connection.HTTPSConnection object at 0x7f08cc46f650>: Failed to establish a new connection: [Errno 111] Connection refused'))
unit-vault-k8s-2: 12:47:08 ERROR unit.vault-k8s/2.juju-log [vault_client] Error while checking Vault health status: HTTPSConnectionPool(host='vault-k8s-2.vault-k8s-endpoints.test-pki-jqcf.svc.cluster.local', port=8200): Max retries exceeded with url: /v1/sys/health (Caused by NewConnectionError('<urllib3.connection.HTTPSConnection object at 0x7f913e8eaa50>: Failed to establish a new connection: [Errno 111] Connection refused'))
unit-vault-k8s-1: 12:47:08 ERROR unit.vault-k8s/1.juju-log [vault_client] Error while checking Vault health status: HTTPSConnectionPool(host='vault-k8s-1.vault-k8s-endpoints.test-pki-jqcf.svc.cluster.local', port=8200): Max retries exceeded with url: /v1/sys/health (Caused by NewConnectionError('<urllib3.connection.HTTPSConnection object at 0x7f9cc0bef110>: Failed to establish a new connection: [Errno 111] Connection refused'))
unit-vault-k8s-2: 12:47:09 ERROR unit.vault-k8s/2.juju-log vault-peers:0: [vault_client] Error while checking Vault health status: HTTPSConnectionPool(host='vault-k8s-2.vault-k8s-endpoints.test-pki-jqcf.svc.cluster.local', port=8200): Max retries exceeded with url: /v1/sys/health (Caused by NewConnectionError('<urllib3.connection.HTTPSConnection object at 0x7f74dcaeb2f0>: Failed to establish a new connection: [Errno 111] Connection refused'))
unit-vault-k8s-1: 12:47:09 ERROR unit.vault-k8s/1.juju-log vault-peers:0: [vault_client] Error while checking Vault health status: HTTPSConnectionPool(host='vault-k8s-1.vault-k8s-endpoints.test-pki-jqcf.svc.cluster.local', port=8200): Max retries exceeded with url: /v1/sys/health (Caused by NewConnectionError('<urllib3.connection.HTTPSConnection object at 0x7f961533b440>: Failed to establish a new connection: [Errno 111] Connection refused'))
unit-self-signed-certificates-0: 12:47:56 ERROR unit.self-signed-certificates/0.juju-log At least 1 matching relation ID not found with the relation name 'send-ca-cert'
unit-self-signed-certificates-0: 12:48:07 ERROR unit.self-signed-certificates/0.juju-log certificates:1: At least 1 matching relation ID not found with the relation name 'send-ca-cert'
unit-self-signed-certificates-0: 12:48:09 ERROR unit.self-signed-certificates/0.juju-log certificates:1: At least 1 matching relation ID not found with the relation name 'send-ca-cert'
unit-self-signed-certificates-0: 12:48:12 ERROR unit.self-signed-certificates/0.juju-log certificates:1: At least 1 matching relation ID not found with the relation name 'send-ca-cert'
unit-self-signed-certificates-0: 12:48:15 ERROR unit.self-signed-certificates/0.juju-log certificates:1: At least 1 matching relation ID not found with the relation name 'send-ca-cert'
unit-self-signed-certificates-0: 12:48:27 ERROR unit.self-signed-certificates/0.juju-log At least 1 matching relation ID not found with the relation name 'send-ca-cert'
unit-self-signed-certificates-0: 12:48:50 ERROR unit.self-signed-certificates/0.juju-log certificates:1: At least 1 matching relation ID not found with the relation name 'send-ca-cert'

[32mINFO    [0m pytest_operator.plugin:plugin.py:1049 Resetting model test-pki-jqcf...
[32mINFO    [0m pytest_operator.plugin:plugin.py:1038    Destroying applications vault-k8s
[32mINFO    [0m pytest_operator.plugin:plugin.py:1038    Destroying applications self-signed-certificates
[32mINFO    [0m pytest_operator.plugin:plugin.py:1038    Destroying applications tls-certificates-requirer
[32mINFO    [0m pytest_operator.plugin:plugin.py:1054 Not waiting on reset to complete.
[32mINFO    [0m pytest_operator.plugin:plugin.py:1025 Forgetting model main...